Workbook

Sheet Violation Log
A1: S.no | B1: Date | C1: Reported By | D1: Shift | E1: Event Trigger Time | F1: Transporter | G1: Vehicle No | H1: Driver Name | I1: Driver ID | J1: GA | K1: Violation | L1: Broadcast Message | M1: Mail Sent | N1: Mail Time | O1: Comments / Remark | P1: Status
A2: 1 | B2: 46082 | C2: S Prabakaran | D2: C | E2: 0.030555556 | F2: =VLOOKUP(G2,'Vehicle List'!A:C,3,0) -> Rahul Roadlines | G2: KA01AM6290 | H2: Subash Chand | I2: AGP/LNG/286 | J2: =VLOOKUP(G2,'Vehicle List'!A:D,4,0) -> Ennore | K2: Observation | L2: Not Applicable | M2: Not Applicable | N2: 0.030555556 | O2: Driver to wear the uniform in duty hours/ Informed LLP | P2: Open | S2: Fatigue | T2: Relayed | U2: Yes
A3: =A2+1 -> 2 | B3: 46082 | C3: S Prabakaran | D3: C | E3: 0.22916667 | F3: =VLOOKUP(G3,'Vehicle List'!A:C,3,0) -> Rahul Roadlines | G3: GJ16AW1575 | H3: Balak Ram Yadav | I3: AGP/LNG/295 | J3: =VLOOKUP(G3,'Vehicle List'!A:D,4,0) -> Hazira | K3: Observation | L3: Not Applicable | M3: Not Applicable | N3: 0.22916667 | O3: Driver to wear the uniform in duty hours/ Informed LLP | P3: Open | S3: Overspeed | T3: Relayed | U3: Yes
A4: =A3+1 -> 3 | B4: 46082 | C4: Karthikeyan S | D4: A | E4: 0.28819444 | F4: =VLOOKUP(G4,'Vehicle List'!A:C,3,0) -> Rahul Roadlines | G4: RJ19GH6331 | H4: Magna Ram | I4: AGP/CNG/BJJ/175 | J4: =VLOOKUP(G4,'Vehicle List'!A:D,4,0) -> BJJ | K4: Overspeed | L4: Not Applicable | M4: Yes | N4: 0.34791667 | O4: Whatsapp msg, mail sent / Informed LLP / Mailed to BJJ Team | P4: Closed | S4: Mobile Usage | T4: Relayed | U4: Yes
A5: =A4+1 -> 4 | B5: 46082 | C5: Karthikeyan S | D5: A | E5: 0.34375 | F5: =VLOOKUP(G5,'Vehicle List'!A:C,3,0) -> Kongunadu Roadlines | G5: KA01AN2568 | H5: Sakthivel | I5: AGP/CNG/KANCHI/029 | J5: =VLOOKUP(G5,'Vehicle List'!A:D,4,0) -> Vellore | K5: Observation | L5: Not Applicable | M5: Not Applicable | N5: 0.34375 | O5: Cabin camera view need to change / Informed LLP | P5: Open | S5: No Seatbelt | T5: Relayed | U5: Yes
A6: =A5+1 -> 5 | B6: 46082 | C6: Karthikeyan S | D6: A | E6: 0.34583333 | F6: =VLOOKUP(G6,'Vehicle List'!A:C,3,0) -> Kongunadu Roadlines | G6: NL01AE4802 | H6: Virendra Kumar Yadav | I6: AGP/LNG/255 | J6: =VLOOKUP(G6,'Vehicle List'!A:D,4,0) -> Ennore | K6: Observation | L6: Not Applicable | M6: Not Applicable | N6: 0.34583333 | O6: Driver to wear the uniform in duty hours/ Informed LLP | P6: Closed | S6: Yawning | T6: Relayed | U6: Yes
A7: =A6+1 -> 6 | B7: 46082 | C7: Karthikeyan S | D7: A | E7: 0.41597222 | F7: =VLOOKUP(G7,'Vehicle List'!A:C,3,0) -> Velan Gogreen Logistics Pvt Ltd | G7: TN33BY1350 | H7: V Manikandan | I7: AGP/CNG/KANCHI/152 | J7: =VLOOKUP(G7,'Vehicle List'!A:D,4,0) -> KNCP | K7: Observation | L7: Not Applicable | M7: Not Applicable | N7: 0.41597222 | O7: LH side camera angle need to change / Informed LLP | P7: Open | S7: Camera Anomaly | T7: Relayed | U7: Yes
A8: =A7+1 -> 7 | B8: 46082 | C8: Karthikeyan S | D8: A | E8: 0.36597222 | F8: =VLOOKUP(G8,'Vehicle List'!A:C,3,0) -> Anisha Logistics | G8: MP04GB5752 | H8: Rakesh Ahirwar | I8: TG/CNG/Bhopal/069 | J8: =VLOOKUP(G8,'Vehicle List'!A:D,4,0) -> Bhopal | K8: Mobile Usage | L8: Not Applicable | M8: Yes | N8: 0.44444444 | O8: Whatsapp msg, mail sent / Informed LLP / Mailed to Bhopal Team | P8: Closed | S8: Night Curfew | T8: Relayed | U8: Yes
A9: =A8+1 -> 8 | B9: 46082 | C9: Karthikeyan S | D9: A | E9: 0.47569444 | F9: =VLOOKUP(G9,'Vehicle List'!A:C,3,0) -> Rahul Roadlines | G9: KA01AM6978 | H9: Jai Prakash Tiwari | I9: AGP/LNG/249 | J9: =VLOOKUP(G9,'Vehicle List'!A:D,4,0) -> Ennore | K9: Mobile Usage | L9: Not Applicable | M9: Yes | N9: 0.48263889 | O9: Whatsapp msg, mail sent / Informed LLP / Mailed to Ennore Team | P9: Closed | S9: Observation | T9: Not Applicable | U9: Not Applicable
A10: =A9+1 -> 9 | B10: 46082 | C10: Praveen Kumar V | D10: B | E10: 0.61666667 | F10: =VLOOKUP(G10,'Vehicle List'!A:C,3,0) -> Kongunadu Roadlines | G10: TN88K3112 | H10: Yuvaraju G | I10: AGP/CNG/CTR/074 | J10: =VLOOKUP(G10,'Vehicle List'!A:D,4,0) -> Chittoor | K10: Observation | L10: Not Applicable | M10: Not Applicable | N10: 0.62222222 | O10: Driver is keeping the mobile in his pocket / Informed LLP | P10: Open | S10: Nearmiss | T10: Not Applicable | U10: Not Applicable
A11: =A10+1 -> 10 | B11: 46082 | C11: Praveen Kumar V | D11: B | E11: 0.61875 | F11: =VLOOKUP(G11,'Vehicle List'!A:C,3,0) -> Expo Trans India Limited | G11: MP04YT8793 | H11: Sundar Lowanshi | I11: TG/CNG/Bhopal/024 | J11: =VLOOKUP(G11,'Vehicle List'!A:D,4,0) -> Bhopal | K11: Observation | L11: Not Applicable | M11: Not Applicable | N11: 0.625 | O11: Driver to wear the uniform in duty hours/ Informed LLP | P11: Closed | S11: Feeling Tired | T11: Relayed | U11: Yes
A12: =A11+1 -> 11 | B12: 46082 | C12: Praveen Kumar V | D12: B | E12: 0.62569444 | F12: =VLOOKUP(G12,'Vehicle List'!A:C,3,0) -> Kongunadu Roadlines | G12: TN88J3816 | H12: Muthukaruppannan G | I12: AGP/CNG/KANCHI/229 | J12: =VLOOKUP(G12,'Vehicle List'!A:D,4,0) -> KNCP | K12: Observation | L12: Not Applicable | M12: Not Applicable | N12: 0.62916667 | O12: Driver is keeping the mobile in his pocket / Informed LLP | P12: Open | S12: Good Observation | T12: Not Applicable | U12: Yes
A13: =A12+1 -> 12 | B13: 46082 | C13: Praveen Kumar V | D13: B | E13: 0.62569444 | F13: =VLOOKUP(G13,'Vehicle List'!A:C,3,0) -> Expo Trans India Limited | G13: KA01AM6186 | H13: PREMCHAND B N | I13: AGP/CNG/KOL/029 | J13: =VLOOKUP(G13,'Vehicle List'!A:D,4,0) -> Kolar | K13: Observation | L13: Not Applicable | M13: Not Applicable | N13: 0.63194444 | O13: AI & Front camera angle need to change / Informed LLP | P13: Open | S13: Continuous driving | T13: Relayed | U13: Yes
A14: =A13+1 -> 13 | B14: 46082 | C14: Praveen Kumar V | D14: B | E14: 0.70069444 | F14: =VLOOKUP(G14,'Vehicle List'!A:C,3,0) -> Kongunadu Roadlines | G14: TN88J4061 | H14: Periyasami | I14: AGP/CNG/KANCHI/081 | J14: =VLOOKUP(G14,'Vehicle List'!A:D,4,0) -> KNCP | K14: Observation | L14: Not Applicable | M14: Not Applicable | N14: 0.70347222 | O14: AI & Rear side camera angle need to change / Informed LLP | P14: Open
A15: =A14+1 -> 14 | B15: 46082 | C15: Praveen Kumar V | D15: B | E15: 0.70138889 | F15: =VLOOKUP(G15,'Vehicle List'!A:C,3,0) -> Dhinesh Transports | G15: TN13AB8624 | H15: Selvaraj V | I15: AGP/CNG/KANCHI/089 | J15: =VLOOKUP(G15,'Vehicle List'!A:D,4,0) -> KNCP | K15: Observation | L15: Not Applicable | M15: Not Applicable | N15: 0.70486111 | O15: Driver disconnect the charging cable in mobile and then use of it /Informed LLP | P15: Closed
A16: =A15+1 -> 15 | B16: 46082 | C16: Praveen Kumar V | D16: B | E16: 0.69652778 | F16: =VLOOKUP(G16,'Vehicle List'!A:C,3,0) -> Oraya Gas India Pvt.Ltd. | G16: GJ39TA2576 | H16: Pradeep Kumar Singh | I16: AGP/LNG/588 | J16: =VLOOKUP(G16,'Vehicle List'!A:D,4,0) -> Dahej | K16: Mobile Usage | L16: Not Applicable | M16: Yes | N16: 0.71527778 | O16: Whatsapp msg, mail sent / Informed LLP / Mailed to Dahej Team | P16: Closed
A17: =A16+1 -> 16 | B17: 46082 | C17: Praveen Kumar V | D17: B | E17: 0.74861111 | F17: =VLOOKUP(G17,'Vehicle List'!A:C,3,0) -> Rahul Roadlines | G17: KA01AM6290 | H17: Subash Chand | I17: AGP/LNG/286 | J17: =VLOOKUP(G17,'Vehicle List'!A:D,4,0) -> Ennore | K17: Observation | L17: Not Applicable | M17: Not Applicable | N17: 0.75069444 | O17: LH & Cabin camera angle need to change / Informed LLP | P17: Open
A18: =A17+1 -> 17 | B18: 46082 | C18: Praveen Kumar V | D18: B | E18: 0.81180556 | F18: =VLOOKUP(G18,'Vehicle List'!A:C,3,0) -> Kongunadu Roadlines | G18: TN88J2175 | H18: Selvam J | I18: AGP/LNG/001 | J18: =VLOOKUP(G18,'Vehicle List'!A:D,4,0) -> Ennore | K18: Observation | L18: Not Applicable | M18: Not Applicable | N18: 0.81388889 | O18: AI & RH & LH camera angle need to change / Informed LLP | P18: Open
A19: =A18+1 -> 18 | B19: 46082 | C19: Praveen Kumar V | D19: B | E19: 0.80902778 | F19: =VLOOKUP(G19,'Vehicle List'!A:C,3,0) -> Rahul Roadlines | G19: KA01AM6978 | H19: Jai Prakash Tiwari | I19: AGP/LNG/249 | J19: =VLOOKUP(G19,'Vehicle List'!A:D,4,0) -> Ennore | K19: Observation | L19: Not Applicable | M19: Not Applicable | N19: 0.81597222 | O19: Driver is keeping the mobile in his pocket / Informed LLP | P19: Open
A20: =A19+1 -> 19 | B20: 46082 | C20: S Prabakaran | D20: C | E20: 0.92569444 | F20: =VLOOKUP(G20,'Vehicle List'!A:C,3,0) -> Anmol Transport | G20: PB11DK2234 | H20: lovepreet singh | I20: TG/CNG/Ludhiana/093 | J20: =VLOOKUP(G20,'Vehicle List'!A:D,4,0) -> Jalandhar | K20: Mobile Usage | L20: Not Applicable | M20: Yes | N20: 0.92569444 | O20: Whatsapp msg, mail sent / Informed LLP / Mailed to Jalandhar Team | P20: Closed
A21: =A20+1 -> 20 | B21: 46082 | C21: S Prabakaran | D21: C | E21: 0.93055556 | F21: =VLOOKUP(G21,'Vehicle List'!A:C,3,0) -> Gas Point | G21: MP09GJ0465 | H21: Sourabh Bhargav | I21: TG/CNG/Bhopal/094 | J21: =VLOOKUP(G21,'Vehicle List'!A:D,4,0) -> Bhopal | K21: Observation | L21: Not Applicable | M21: Not Applicable | N21: 0.93055556 | O21: No seat belt malfunctioning / Informed LLP | P21: Closed
A22: =A21+1 -> 21 | B22: 46082 | C22: S Prabakaran | D22: C | E22: 0.97847222 | F22: =VLOOKUP(G22,'Vehicle List'!A:C,3,0) -> Expo Trans India Limited | G22: NL01AH9067 | H22: SALMAN | I22: AGP/LNG/565 | J22: =VLOOKUP(G22,'Vehicle List'!A:D,4,0) -> Kochi | K22: Observation | L22: Not Applicable | M22: Not Applicable | N22: 0.97847222 | O22: Driver to wear the uniform in duty hours/ Informed LLP | P22: Open
A23: =A22+1 -> 22 | B23: 46083 | C23: S Prabakaran | D23: C | E23: 0.059027778 | F23: =VLOOKUP(G23,'Vehicle List'!A:C,3,0) -> Kongunadu Roadlines | G23: KA01AN2568 | H23: Sakthivel | I23: AGP/CNG/KANCHI/029 | J23: =VLOOKUP(G23,'Vehicle List'!A:D,4,0) -> Vellore | K23: Observation | L23: Not Applicable | M23: Not Applicable | N23: 0.059027778 | O23: Driver to rectify the Cabin camera View / Informed LLP | P23: Open
A24: =A23+1 -> 23 | B24: 46083 | C24: S Prabakaran | D24: C | E24: 0.088888889 | F24: =VLOOKUP(G24,'Vehicle List'!A:C,3,0) -> Kongunadu Roadlines | G24: KA01AM5032 | H24: ANOOP M.U | I24: AGP/LNG/555 | J24: =VLOOKUP(G24,'Vehicle List'!A:D,4,0) -> Kochi | K24: Observation | L24: Not Applicable | M24: Not Applicable | N24: 0.088888889 | O24: Driver to remove the object from cabin camera / Informed LLP | P24: Open
A25: =A24+1 -> 24 | B25: 46083 | C25: S Prabakaran | D25: C | E25: 0.21041667 | F25: =VLOOKUP(G25,'Vehicle List'!A:C,3,0) -> Green Planet | G25: GJ05CU1486 | H25: Rajesh Kumar | I25: AGP/LNG/170 | J25: =VLOOKUP(G25,'Vehicle List'!A:D,4,0) -> Kochi | K25: Observation | L25: Not Applicable | M25: Not Applicable | N25: 0.21041667 | O25: Driver why the vehicle has parked at near by roadside / Informed LLP | P25: Open
... A48: =A47+1 -> 47 | B48: 46084 | C48: Bhuvan VK | D48: C | E48: 0.013194444 | F48: =VLOOKUP(G48,'Vehicle List'!A:C,3,0) -> Oraya Gas India Pvt.Ltd. | G48: GJ12BX5648 | H48: SHIV NARAYAN JAISWAL | I48: AGP/LNG/594 | J48: =VLOOKUP(G48,'Vehicle List'!A:D,4,0) -> Kochi | K48: Mobile Usage | L48: Not Applicable | M48: Yes | N48: 0.10347222 | O48: Whatsapp msg, mail sent / Informed LLP / Mailed to Kochi Team | P48: Closed
A49: =A48+1 -> 48 | B49: 46084 | C49: Bhuvan VK | D49: C | E49: 0.098611111 | F49: =VLOOKUP(G49,'Vehicle List'!A:C,3,0) -> Kongunadu Roadlines | G49: TN88J2175 | H49: Selvam J | I49: AGP/LNG/001 | J49: Ennore | K49: Observation | L49: Not Applicable | M49: Not Applicable | N49: 0.098611111 | O49: AI & LH camera angle need to change / Informed LLP | P49: Open
A50: =A49+1 -> 49 | B50: 46084 | C50: Bhuvan VK | D50: C | E50: 0.11736111 | F50: =VLOOKUP(G50,'Vehicle List'!A:C,3,0) -> Kongunadu Roadlines | G50: TN88H6575 | H50: AJAY KUMAR | I50: AGP/LNG/581 | J50: =VLOOKUP(G50,'Vehicle List'!A:D,4,0) -> Kochi | K50: Observation | L50: Not Applicable | M50: Not Applicable | N50: 0.11736111 | O50: Driver to remove the object from cabin camera / Informed LLP | P50: Open
A51: =A50+1 -> 50 | B51: 46084 | C51: Bhuvan VK | D51: C | E51: 0.11875 | F51: =VLOOKUP(G51,'Vehicle List'!A:C,3,0) -> Kongunadu Roadlines | G51: NL01AF1651 | H51: PREM SINGH | I51: AGP/LNG/543 | J51: =VLOOKUP(G51,'Vehicle List'!A:D,4,0) -> Hazira | K51: Yawning | L51: Not Applicable | M51: Yes | N51: 0.18541667 | O51: Whatsapp msg, mail sent / Informed LLP / Mailed to Dahej Team | P51: Closed
A52: =A51+1 -> 51 | B52: 46084 | C52: Bhuvan VK | D52: C | E52: 0.125 | F52: =VLOOKUP(G52,'Vehicle List'!A:C,3,0) -> Rahul Roadlines | G52: NL01AH0275 | H52: Santosh Kumar Mishra | I52: AGP/LNG/252 | J52: =VLOOKUP(G52,'Vehicle List'!A:D,4,0) -> Dahej | K52: Observation | L52: Not Applicable | M52: Not Applicable | N52: 0.125 | O52: Driver doing single hand driving continuously / Informed LLP | P52: Open
A53: =A52+1 -> 52 | B53: 46084 | C53: Bhuvan VK | D53: C | E53: 0.14027778 | F53: =VLOOKUP(G53,'Vehicle List'!A:C,3,0) -> Kongunadu Roadlines | G53: TN88L9300 | H53: AJITH KUMAR S | I53: AGP/CNG/AKT/152 | J53: =VLOOKUP(G53,'Vehicle List'!A:D,4,0) -> AKT | K53: Mobile Usage | L53: Not Applicable | M53: Yes | N53: 0.17986111 | O53: Whatsapp msg, mail sent / Informed LLP / Mailed to AKT Team | P53: Closed
A54: =A53+1 -> 53 | B54: 46084 | C54: Bhuvan VK | D54: C | E54: 0.25277778 | F54: =VLOOKUP(G54,'Vehicle List'!A:C,3,0) -> Expo Trans India Limited | G54: KA01AN9662 | H54: DHAREPPA | I54: AGP/CNG/CHK/493 | J54: =VLOOKUP(G54,'Vehicle List'!A:D,4,0) -> Chittoor | K54: Observation | L54: Not Applicable | M54: Not Applicable | N54: 0.25277778 | O54: Unknown person in Co Driver seat / Informed LLP | P54: Open
A55: =A54+1 -> 54 | B55: 46084 | C55: S Prabakaran | D55: A | E55: 0.28194444 | F55: =VLOOKUP(G55,'Vehicle List'!A:C,3,0) -> Kongunadu Roadlines | G55: TN88J2175 | H55: Selvam J | I55: AGP/LNG/001 | J55: =VLOOKUP(G55,'Vehicle List'!A:D,4,0) -> Ennore | K55: Observation | L55: Not Applicable | M55: Not Applicable | N55: 0.28194444 | O55: AI & LH camera angle need to change / Informed LLP | P55: Open
A56: =A55+1 -> 55 | B56: 46084 | C56: S Prabakaran | D56: A | E56: 0.30208333 | F56: =VLOOKUP(G56,'Vehicle List'!A:C,3,0) -> Rahul Roadlines | G56: RJ19GH7141 | H56: Sahdev | I56: AGP/CNG/BJJ/033 | J56: =VLOOKUP(G56,'Vehicle List'!A:D,4,0) -> BJJ | K56: Observation | L56: Not Applicable | M56: Not Applicable | N56: 0.30208333 | O56: Vehicle has parked at roadside/ Informed LLP | P56: Closed
A57: =A56+1 -> 56 | B57: 46084 | C57: S Prabakaran | D57: A | E57: 0.31944444 | F57: =VLOOKUP(G57,'Vehicle List'!A:C,3,0) -> Anisha Logistics | G57: MP04GB5705 | H57: Lal Singh Meena | I57: TG/CNG/Bhopal/006 | J57: =VLOOKUP(G57,'Vehicle List'!A:D,4,0) -> Bhopal | K57: Observation | L57: Not Applicable | M57: Not Applicable | N57: 0.31944444 | O57: Driver to wear the uniform in duty hours/ Informed LLP | P57: Open
A58: =A57+1 -> 57 | B58: 46084 | C58: S Prabakaran | D58: A | E58: 0.35416667 | F58: =VLOOKUP(G58,'Vehicle List'!A:C,3,0) -> Expo Trans India Limited | G58: KA01AM6186 | H58: PREMCHAND B N | I58: AGP/CNG/KOL/029 | J58: =VLOOKUP(G58,'Vehicle List'!A:D,4,0) -> Kolar | K58: Observation | L58: Not Applicable | M58: Not Applicable | N58: 0.35416667 | O58: AI & Front camera angle need to change / Informed LLP | P58: Open
A59: =A58+1 -> 58 | B59: 46084 | C59: S Prabakaran | D59: A | E59: 0.38402778 | F59: =VLOOKUP(G59,'Vehicle List'!A:C,3,0) -> Kongunadu Roadlines | G59: TN88J3078 | H59: Vedhamani | I59: AGP/CNG/KANCHI/227 | J59: =VLOOKUP(G59,'Vehicle List'!A:D,4,0) -> KNCP | K59: Mobile Usage | L59: Not Applicable | M59: Yes | N59: 0.38402778 | O59: Whatsapp msg, mail sent / Informed LLP / Mailed to KNCP Team | P59: Closed
A60: =A59+1 -> 59 | B60: 46084 | C60: S Prabakaran | D60: A | E60: 0.45277778 | F60: =VLOOKUP(G60,'Vehicle List'!A:C,3,0) -> Expo Trans India Limited | G60: KA01AN9662 | H60: DHAREPPA | I60: AGP/CNG/CHK/493 | J60: =VLOOKUP(G60,'Vehicle List'!A:D,4,0) -> Chittoor | K60: Observation | L60: Not Applicable | M60: Not Applicable | N60: 0.45277778 | O60: Cabin camera angle need to change / Informed LLP | P60: Open
A61: =A60+1 -> 60 | B61: 46084 | C61: S Prabakaran | D61: A | E61: 0.47777778 | F61: =VLOOKUP(G61,'Vehicle List'!A:C,3,0) -> Velan Gogreen Logistics Pvt Ltd | G61: TN33BY1350 | H61: Manikandan V | I61: AGP/CNG/KANCHI/201 | J61: =VLOOKUP(G61,'Vehicle List'!A:D,4,0) -> KNCP | K61: Observation | L61: Not Applicable | M61: Not Applicable | N61: 0.47777778 | O61: RH side camera angle need to change / Informed LLP | P61: Open
... A424: =A423+1 -> 423 | B424: 46095 | C424: Bhuvan VK | D424: C | E424: 0.97916667 | F424: =VLOOKUP(G424,'Vehicle List'!A:C,3,0) -> Expo Trans India Limited | G424: MP04YT8662 | H424: Manish Solanki | I424: TG/CNG/Bhopal/059 | J424: =VLOOKUP(G424,'Vehicle List'!A:D,4,0) -> Bhopal | K424: Mobile Usage | L424: Not Applicable | M424: Yes | N424: 0.98472222 | O424: Whatsapp msg, mail sent / Informed LLP / Mailed to Bhopal Team | P424: Closed
...

Sheet Shift Details
A1: S.No | B1: Date | C1: Shift in-charge | D1: Shift | E1: Events triggered in portal (Post filtration) | F1: Events captured through monitoring | G1: Observations | H1: Observation brief | I1: Action taken Events | J1: Pending events handover to next shift | K1: Remarks
A2: 1 | B2: 01.03.2026 | C2: Karthikeyan S | D2: A(06:00 to 14:00 hrs) | E2: 2 | F2: 1 | G2: 3 | H2: Cabin & LH side camera view need to change and Driver to wear the uniform in duty hours | I2: 3 | J2: Nil | K2: PM Alert,LMS Consolidated, Unknown Stoppage & MCV detention
A3: 1 | B3: 01.03.2026 | C3: Praveen Kumar V | D3: B(14:00 to 22:00 hrs) | E3: 0 | F3: 1 | G3: 9 | H3: Driver is keeping the mobile in his pocket, Driver to wear the uniform in duty hours, AI,RH & LH camera angle need to change, Cabin,Front & Rear side camera angle need to change & Driver disconnect the charging cable in mobile and then use of it | I3: 1 | J3: Nil | K3: Weather & Violation Report, MCV Detention & Unknown stoppage
A4: 1 | B4: 01.03.2026 | C4: Prabakaran S | D4: C (22:00 to 6:00 hrs) | E4: 0 | F4: 1 | G4: 5 | H4: No seat belt malfunctioning, Driver to wear the uniform in duty hours, Driver to rectify the Cabin camera View, Driver to remove the object from cabin camera,Driver why the vehicle has parked at near by roadside . | I4: 0 | J4: Jalandar violation mail pending | K4: Violation, weather & Curfew status Report
A5: 1 | B5: 02.03.2026 | C5: Karthikeyan S | D5: A(06:00 to 14:00 hrs) | E5: 2 | F5: 1 | G5: 4 | H5: Remove the object from Cabin camera, Cabin camera angle need to change and Vehicle has parked at roadside | I5: 3 | J5: Nil | K5: PM Alert,LMS Consolidated, Unknown Stoppage & MCV detention
A6: 1 | B6: 02.03.2026 | C6: Prabakaran S | D6: B(14:00 to 22:00 hrs) | E6: 1 | F6: 1 | G6: 9 | H6: LH & Cabin camera angle need to change,LH & AI camera angle need to change,Driver don't use bluetooth headset while driving,Driver doing single hand driving continuously ,Cabin camera angle need to change , Driver do not drink water while driving, Vehicle has parked at roadside, AI camera angle need to change | I6: 2 | J6: Nil | K6: Weather & Violation Report, MCV Detention & Unknown stoppage
A7: 1 | B7: 02.03.2026 | C7: Bhuvan VK | D7: C (22:00 to 6:00 hrs) | E7: 5 | F7: 0 | G7: 5 | H7: Driver to remove the object from cabin camera, LH & AI camera angle need to change, Driver doing single hand driving continuously, Unknown person in Co Driver seat | I7: 5 | J7: Nil | K7: Violation, weather & Curfew status Report
A8: 1 | B8: 03.03.2026 | C8: Prabakaran S | D8: A(06:00 to 14:00 hrs) | E8: 0 | F8: 1 | G8: 7 | H8: AI & LH camera angle need to change, Vehicle has parked at roadside, Driver to wear the uniform in duty hours, AI & Front camera angle need to change,Cabin camera angle need to change . | I8: 1 | J8: Nil | K8: PM Alert,LMS Consolidated, Unknown Stoppage & MCV detention
A9: 1 | B9: 03.03.2026 | C9: Praveen Kumar V | D9: B(14:00 to 22:00 hrs) | E9: 1 | F9: 0 | G9: 8 | H9: Cabin camera view need to change, Driver to wear the uniform in duty hours, LH & Cabin camera angle need to change, Driver do not drink water while driving, Driver disconnect the charging cable in mobile and then use of it & Driver doing distraction activities while driving. | I9: 1 | J9: Nil | K9: Weather & Violation Report, MCV Detention & Unknown stoppage
A10: 1 | B10: 02.03.2026 | C10: Bhuvan VK | D10: C (22:00 to 6:00 hrs) | E10: 0 | F10: 2 | G10: 6 | H10: Driver to remove the object from cabin camera, Unknown person in Co Driver seat, Driver he is fine or not, Driver do not drink water while driving | I10: 2 | J10: Nil | K10: Violation, weather & Curfew status Report
A11: 1 | B11: 04.03.2026 | C11: Prabakaran S | D11: A(06:00 to 14:00 hrs) | E11: 0 | F11: 1 | G11: 7 | H11: LH camera angle need to change, Vehicle has parked at roadside, Driver to wear the uniform in duty hours, AI & Front camera angle need to change,Rear camera angle need to change . | I11: 1 | J11: Nil | K11: PM Alert,LMS Consolidated, Unknown Stoppage & MCV detention
A12: 1 | B12: 04.03.2026 | C12: Praveen Kumar V | D12: B(14:00 to 22:00 hrs) | E12: 1 | F12: 3 | G12: 5 | H12: LH & Cabin camera angle need to change, RH side camera angle need to change, Driver to wear the uniform in duty hours, Driver disconnect the charging cable in mobile and then use of it & Driver is keeping the mobile in his pocket | I12: 4 | J12: Nil | K12: Weather & Violation Report, MCV Detention & Unknown stoppage
A13: 1 | B13: 04.03.2026 | C13: Bhuvan VK | D13: C (22:00 to 6:00 hrs) | E13: 2 | F13: 0 | G13: 9 | H13: Driver to remove the object from Rear camera, Unknown person in Co Driver seat, Driver he is fine or not, Driver do not drink water while driving, Driver is keeping the mobile in his pocket, AI &RH camera angle need to change. | I13: 2 | J13: Nil | K13: Violation, weather & Curfew status Report
... A53: 1 | B53: 18.03.2026 | C53: Bhuvan VK | D53: A(06:00 to 14:00 hrs) | E53: 1 | F53: 3 | G53: 10 | H53: Rear& RH side Camera angle need to change, Remove the object from Front camera, Unknown person in Co Driver seat, Vehicle has parked at roadside, Driver he is fine or not, Driver disconnect the charging cable in mobile and then use of it | I53: 4 | J53: NIL | K53: PM Alert,LMS Consolidated, Unknown Stoppage & MCV detention
N398: 0.53819444

Sheet ERV Log 
A1: S.no | B1: Date | C1: Reported By | D1: Shift | E1: Event Trigger Time | F1: Transportar name | G1: Vehicle No | H1: Driver Name | I1: Driver ID | J1: GA | K1: Violation | L1: Broadcast Message | M1: Mail Sent | N1: Mail Time | O1: Comments / Remark | P1: Status
A2: 1 | B2: 18.10.2024 | C2: K.Gopinath | D2: C | E2: 0.30486111 | G2: MP16ZE8457 | H2: Ganesh Dasari | I2: Not created | J2: Nellore | K2: No Seatbelt | L2: Not Applicable | M2: Yes | N2: 0.42916667 | O2: Whatsapp msg, mail sent | P2: Closed
A3: =A2+1 -> 2 | B3: 17.10.2024 | C3: Rajesh Kumar | D3: B | E3: 0.4125 | G3: AP39UV7392 | H3: Raju | I3: Not created | J3: Tirupathi | K3: Mobile Usage | L3: Not Applicable | M3: Yes | N3: 0.65138889 | O3: Whatsapp msg, mail sent | P3: Closed
A4: =A3+1 -> 3 | B4: 17.10.2024 | C4: Rajesh Kumar | D4: B | E4: 0.4125 | G4: AP39UV7392 | H4: Raju | I4: Not created | J4: Tirupathi | K4: Overspeed | L4: Not Applicable | M4: Yes | N4: 0.65138889 | O4: Whatsapp msg, mail sent | P4: Closed
A5: =A4+1 -> 4 | B5: 17.10.2024 | C5: K.Gopinath | D5: C | E5: 0.96180556 | G5: TN18BS5173 | H5: Deepak | I5: Not created | J5: Kanchipuram | K5: Observation | L5: Not Applicable | M5: Yes | N5: 0.96527778 | O5: AI camera angle need to be changed | P5: Closed
A6: =A5+1 -> 5 | B6: 21.10.2024 | C6: Napolean | D6: G | E6: 0.48611111 | G6: MH14LL6819 | H6: Parmesh E/Pradeep | I6: Not created | J6: CHK | K6: No Seatbelt | L6: Not Applicable | M6: Yes | N6: 0.48611111 | O6: Whatsapp msg, mail sent | P6: Closed
A7: =A6+1 -> 6 | B7: 21.10.2024 | C7: K.Gopinath | D7: B | E7: 0.625 | G7: TN18BS5173 | H7: Deepak | I7: Not created | J7: Kanchipuram | K7: Mobile Usage | L7: Not Applicable | M7: Yes | N7: 0.64375 | O7: Whatsapp msg, mail sent / Mailed to O&M Team | P7: Closed
A8: =A7+1 -> 7 | B8: 22.10.2024 | C8: K.Gopinath | D8: B | E8: 0.75 | G8: GJ02AT6498 | H8: Ezhil | I8: Not created | J8: Vellore | K8: Observation | L8: Not Applicable | M8: Yes | N8: 0.75694444 | O8: AI camera angle need to be changed | P8: Open
A9: =A8+1 -> 8 | B9: 23.10.2024 | C9: K.Gopinath | D9: A | E9: 0.45 | G9: AP39SJ4897 | H9: Mahesh | I9: Not created | J9: ANK | K9: Overspeed | L9: Not Applicable | M9: Yes | N9: 0.48958333 | O9: Whatsapp msg, mail sent / Mailed to O&M Team | P9: Closed
A10: =A9+1 -> 9 | B10: 23.10.2024 | C10: Praveen Kumar V | D10: B | E10: 0.60416667 | G10: MH14LL7256 | H10: Prabhu | I10: Not created | J10: Ramanathapuram | K10: Overspeed | L10: Not Applicable | M10: Yes | N10: 0.48958333 | O10: Whatsapp msg, mail sent / Mailed to O&M Team | P10: Closed
A11: =A10+1 -> 10 | B11: 24.10.2024 | C11: K.Gopinath | D11: A | E11: 0.49236111 | G11: AP39UV7392 | H11: Raju | I11: Not created | J11: Tirupathi | K11: Overspeed | L11: Not Applicable | M11: Yes | N11: 0.50694444 | O11: Whatsapp msg, mail sent / Mailed to O&M Team | P11: Closed
A12: =A11+1 -> 11 | B12: 30.10.2024 | C12: K.Gopinath | D12: A | E12: 0.40277778 | G12: AP39SJ4897 | H12: Madhu Sudhan | I12: Not created | J12: ANK | K12: Mobile Usage | L12: Not Applicable | M12: Yes | N12: 0.48958333 | O12: Whatsapp msg, mail sent / Mailed to O&M Team | P12: Closed
A13: =A12+1 -> 12 | B13: 25.11.2024 | C13: K.Gopinath | D13: A | E13: 0.40277778 | G13: TN18BS5122 | H13: Deepak | I13: Not created | J13: Kanchipuram | K13: Observation | L13: Not Applicable | M13: Not Applicable | N13: 0.44930556 | O13: AI camera angle need to be changed | P13: Open
A14: =A13+1 -> 13 | B14: 26.11.2024 | C14: K.Gopinath | D14: A | E14: 0.43055556 | G14: AP39SJ4897 | H14: Mahesh | I14: Not created | J14: ANK | K14: Observation | L14: Not Applicable | M14: Not Applicable | N14: 0.45277778 | O14: Front camera angle need to be changed | P14: Open
... A16: =A15+1 -> 15 | B16: 03.12.2024 | C16: K.Gopinath | D16: B | E16: 0.78958333 | G16: RJ19GJ3883 | H16: Unassigned | I16: Not created | J16: BJJ | K16: Mobile Usage | L16: Not Applicable | M16: Yes | N16: 0.79513889 | O16: Whatsapp msg, mail sent / Mailed to O&M Team | P16: Closed
A17: 16 | B17: 23.01.2025 | C17: K.Gopinath | D17: B | E17: 0.75833333 | G17: MH14LL7256 | H17: Prabhu | I17: Not created | J17: Ramanathapuram | K17: Observation | L17: Not Applicable | M17: Not Applicable | N17: 0.77847222 | O17: AI & Front camera angle need to be changed | P17: Open
A18: 17 | B18: 45784 | C18: Karthikeyan S | D18: A | E18: 0.40972222 | G18: AP39UV7392 | J18: Tirupathi | K18: Observation | L18: Not Applicable | M18: Not Applicable | N18: 0.40972222 | O18: AI camera angle need to be changed | P18: Open
A19: 18 | B19: 45784 | C19: Karthikeyan S | D19: A | E19: 0.41111111 | G19: RJ07GE2182 | J19: AKT | K19: Observation | L19: Not Applicable | M19: Not Applicable | N19: 0.41111111 | O19: AI camera angle need to be changed | P19: Open

Sheet Log Data 
A1: GA Location list | B1: Logistics Co-ordinator | C1: Logistics Email Id | D1: Logistics Contact | E1: HSE Co-ordinator | F1: HSE contact no | G1: HSE Contact No | H1: GA Head | I1: Marketing | J1: O&M Head | K1: O&M Contact No
A2: ANK | B2: Sampath FarKan | C2: sampath.kumar@think-gas.com c.logistics.ank@think-gas.com | D2: 96328 76505 73376 45424 | E2: Sushil Rambabu Kathuria Devendar Sircilla shisira kumar pradhan | F2: sushil.rk@think-gas.com shisir.kumar@think-gas.com devendar.sircilla@think-gas.com | G2: 7490967996 6381038583 6200692003 | H2: Gautam Anand (Zonal head) gautam.anand@think-gas.com Aditya (Dist Mgr) aditya.vardhan@think-gas.com | I2: prasad@agppratham.com | J2: shisira kumar pradhan | K2: 9989102704
A3: BKR (Bagalkot, Koppala, Raichur) | B3: Mohammed Usman , Basvaraj, MEHABOOB | C3: mohammed.usman@think-gas.com c.logistics.bkr@think-gas.com | D3: 63643 53668 88848 66005 80734 56061 | E3: Viswajith patil Mruthunjayya S | F3: vishwajit.patil@think-gas.com , mruthunjayya.s@think-gas.com | G3: 9758277746 8129862434 8590019247 | H3: Jagadish Iranna Purli jagadish.purli@think-gas.com sanjeevkumar.s@think-gas.com | I3: sumit.dutta@agppratham.com | J3: arunkumar.n@think-gas.com | K3: 9972389367
A4: Dahej (Terminal) | B4: Ranjit , Sagar sunil Rajput, Aditya | C4: ranjit.singh@think-gas.com c.hazira.logistics@think-gas.com sagar.rajput@think-gas.com | D4: 82204 86222 97986 82553 97631 07271 | E4: Vinay Kumar Rai | F4: vinay.kumar@think-gas.com | G4: 7041638434 9099950955 | H4: sundar rajan sundar.rajan@think-gas.com, Deepak Patahk deepak.pathak@think-gas.com
A5: CHK (Chikmagalur,Hassan,Kodagu) | B5: Saqlain, punith Swaroop | C5: saqlain.katgeri@think-gas c.logistics.hassan@think-gas.com | D5: 84950 69683 73536 67393 93537 49600 | E5: Ajeet Kumar Prajapati , Bhavin | F5: ajeet.kumar@think-gas.com bhavin.kantilal@think-gas.com | G5: 9824476545 | H5: Basavaraju K M basavaraju.km@think-gas.com (Deputy) Brajesh singh (Zonal) | I5: karthik.ks@agppratham.com, nitin.huilgol@agppratham.com pravin.vishvanathe@think-gas.com | J5: bhavin.kantilal@think-gas.com | K5: 7043700191
A6: BJJ (Barmer,Jodhpur, Jaisalmer) | B6: Sanjan,Sahil, Arjun Pushpendra, | C6: sahil.rehman@think-gas.com bjj.logistics@think-gas.com sanjan.singh@think-gas.com | D6: 7905467715, 99283 99940, 9835567385 | E6: Vinay Kumar Rai | F6: vinay.kumar@think-gas.com | G6: 7041638434 9099950955 | H6: vinod chawada vinod.chawada@think-gas.com rohit kumar rohit.kumar@think-gas.com (district manager) | I6: darpan.chaudhary@agppratham.com | J6: sunil bishnoi sunil.bishnoi@think-gas.com (Deputy) | K6: 8600046934
A7: KV (Kalburgi, Vijayapura) | B7: Mazhar ahmed, Sanjay, Mustafa | C7: mazhar.ahmed@think-gas.com kv.logistics@think-gas.com c.logistics.kv@think-gas.com | D7: 91087 91619 78924 54445 95384 95503 | E7: Amit Kumar Singh,Ramesh Reddy | F7: amit.singh@think-gas.com | G7: 7907134312 8306767467 | H7: Rangarajan Seshadri s.rangarajan@think-gas.com | I7: prayag.mishra@agppratham.com | J7: Rahul kumar, ,Ramesh Reddy | K7: Ram - 9700432509
A8: Kanchipuram | B8: Vijaykumar Arul , Ashok , Parthi | C8: vijay.r@think-gas.com c.logistics.kanchipuram@think-gas.com | D8: 95001 99497 88833 46843 70940 43883 9500429658 | E8: Sebastian Stalin | F8: sebastian.stalin@think-gas.com | G8: 7708466438 9521867403 | H8: Thirukumaran NT thirukkumaran.nt@think-gas.com, | I8: k.radhakrishnan@agppratham.com | J8: Aftab.Alam@think-gas.com | K8: 8873744466
A9: Kochi (Terminal) | B9: Lal.Bahadur, Gokul, Sathish, | C9: cochin.logistics@think-gas.com lal.bahadur@thinkgas.com sathish.v@think-gas.com | D9: 94167 49002 89214 38468 755002 8988 | E9: Pawan Madhukar Jawanjal | F9: pawan.jawanjal@think-gas.com | G9: 9850069937 9373152148 9008939348 | H9: sundar rajan sundar.rajan@think-gas.com, Deepak Patahk deepak.pathak@think-gas.com
A10: Kolar | B10: Logesh Babu | C10: Logesh.babu@think-gas.com | D10: 95248 17630 | E10: Dhamodaran R Akshith S.R. Priyabrata Datta | F10: dhamodaran.rajendran@think-gas.com | G10: 9655888975 | H10: Gautam Anand(Zonal head) gautam.anand@think-gas.com | I10: gautam.anand@agppratham.com | J10: Akshith S.R. | K10: 9962314312
A11: MMC (Mysore,Mandya,Chamrajnagar) | B11: Lokesh S, Yogesh | C11: lokesh.s@think-gas.com mmc.logistics@think-gas.com | D11: 97425 72117 87227 10368 | E11: Santhosh A | F11: santhosh.a@think-gas.com | G11: 9738407975 9650699982 | H11: Sanjit kumar suman | I11: nitin.huilgol@agppratham.com madankumar.s@think-gas.com | J11: bhavin.kantilal@think-gas.com | K11: 7043700191
A12: Nellore | B12: Jeevan | C12: jeevan.kumar@think-gas.com c.logistics.tirupathi@think-gas.com | D12: 98490 26511 | E12: Venkata sabari | F12: venkata.sabaribabu@think-gas.com | G12: 7981357484 | H12: Gautam Anand (Zonal head)gautam.anand@think-gas.com Anil Kumar DV (Deputy) anilkumar.dv@think-gas.com | I12: Amrendra Kumar <amrendra@agppratham.com> | J12: Ramit Mann ramit.mann@think-gas.com | K12: 9711404163
A13: UHS (Uttarkannad,Haveri, Shivamoga) | B13: Chaitanya Akash Shivu | C13: chaithanya.indaje@think-gas.com c.logistics.uhs@think-gas.com | D13: 87225 53430 9380071691 9945185804 | E13: Sharath Kumar Shetty B, | F13: sharath.shetty@think-gas.com | G13: 9686797948 9601161848 | H13: Manjunath manjunath@think-gas.com (deputy) | I13: santosh.kulkarni@agppratham.com | J13: martinraju@think-gas.com | K13: 9481111106
A14: Tirupathi | C14: c.logistics.tirupathi@think-gas.com | D14: 93819 61903 | E14: Venkata sabari | F14: venkata.sabaribabu@think-gas.com | G14: 9000160565 | H14: Gautam Anand (Zonal head)gautam.anand@think-gas.com Dammu srinu dammu.srinu@think-gas.com 9866187186 | I14: prasad@agppratham.com | J14: dammu.srinu@think-gas.com | K14: 9866187186
A15: AKT (Alappuzha,Kollam, Trivandrum, Cherthala) | B15: Jayakrishann, Gowtham, shambu | C15: c.logistics.akt1@think-gas.com jayakrishnan.ng@think-gas.com c.logistics.akt@think-gas.com | D15: 96338 70757 96333 18880 95399 89393 81296 05611 94477 08550 81398 08602 | E15: Roshan,Pawan Madhukar Jawanjal Akhil Vijayan Sarath A | F15: roshan.p@think-gas.com, pawan.jawanjal@think-gas.com akhil.vijayan@think-gas.com sarath.a@think-gas.com | G15: 9850069937 9373152148 9008939348 7763807054 | H15: Deepu John deepu.john@think-gas.com,Vijai Anand vijai.anand@think-gas.com | I15: srinath.kumar@agppratham.com | J15: Sankar Dhayal Theenathayalan sankar.dhayal@think-gas.com, Praveen Davis praveen.davis@think-gas.com | K15: 8451945219
A16: Vellore | B16: Logesh Babu | C16: Logesh.babu@think-gas.com vellore.logistics@think-gas.com | D16: 96883 79258 94883 66039 | E16: Dhamodaran R Akshith S.R. | F16: dhamodaran.rajendran@think-gas.com | G16: 9655888975 | H16: Gautam Anand gautam.anand@think-gas.com(Zonal head), (dist manager | I16: B Hemachandran <b.hemachandran@agppratham.com> | J16: mohammad.kabeer@think-gas.com | K16: 9962314312
A17: Ramanathapuram | B17: Martin , Mohan , Prabakaran | C17: rmd.logistics@think-gas.com , c.mdpe1.ramnad@think-gas.com, c.onmramnad1@think-gas.com, prabakaran.t@think-gas.com | D17: 85519 86277, 91597 34678, 63699 51854 | E17: Ramesh Kumar | F17: rameshkumar.m@think-gas.com | G17: 8870176186 | H17: Epoomari Sivan epoomari.sivan@think-gas.com | I17: Karthik <karthik.baskaran@agppratham.com> | J17: rameshkumar.m@think-gas.com | K17: 8870176186
A18: Ennore (Terminal) | B18: Fyzan Nivin Haresh | C18: c.logistics.ennore@think-gas.com mohammed.fyzan@think-gas.com haresh.jk@think-gas.com | D18: 91647 96655 9514677570, 824864 1266 | E18: Sebastian Stalin | F18: sebastian.stalin@think-gas.com | G18: 7708466438 9521867403 | H18: sundar rajan sundar.rajan@think-gas.com, Deepak Patahk deepak.pathak@think-gas.com
A19: Jalandar | B19: Dawinder Gurinder | H19: darpan.chaudhary@think-gas.com | J19: Gaurav.Sabharwal@think-gas.com
A20: Begusarai | B20: Rakesh Singh | H20: Vijay.Tiwari@think-gas.com | J20: Prabhakar.Kumar@think-gas.com
A21: Bhopal | B21: Yogesh Bharmal | H21: Durga.Shankar@think-gas.com | J21: Tushar.Bari@think-gas.com
A22: Baghpat | B22: Rakesh Singh | H22: Vikalp.Shukla@think-gas.com | J22: Parush.Kohli@think-gas.com
A23: Shivpuri | B23: Manish Kumar Bhathi | H23: priyank.jain@think-gas.com | J23: priyank.jain@think-gas.com
A24: Kangara | B24: Harimesh Padha | H24: darpan.chaudhary@think-gas.com | J24: darpan.chaudhary@think-gas.com
A25: Ludhiana | B25: Dawinder Gurinder | H25: vishalgiri.goswami@think-gas.com | J25: Gaurav.Sabharwal@think-gas.com

Sheet Vehicles List new
A1: VehicleNumber | B1: VehicleType | C1: Transporter Name | D1: GALocation
A2: KA01AL4119 | B2: LNG | C2: Kongunadu Roadlines | D2: Dahej
A3: KA01AL3719 | B3: LNG | C3: Kongunadu Roadlines | D3: Dahej
A4: TN87B6394 | B4: LNG | C4: Kongunadu Roadlines | D4: Ennore
A5: TN87B6483 | B5: LNG | C5: Kongunadu Roadlines | D5: Ennore
A6: TN87B7069 | B6: LNG | C6: Kongunadu Roadlines | D6: Ennore
A7: KA01AL6761 | B7: LNG | C7: Kongunadu Roadlines | D7: Dahej
A8: KA01AL7519 | B8: LNG | C8: Kongunadu Roadlines | D8: Ennore
A9: KA01AL9139 | B9: LNG | C9: Kongunadu Roadlines | D9: Ennore
A10: TN88H6575 | B10: LNG | C10: Kongunadu Roadlines | D10: Kochi
A11: TN88H6508 | B11: LNG | C11: Kongunadu Roadlines | D11: Kochi
A12: NL01AE4803 | B12: LNG | C12: Kongunadu Roadlines | D12: Ennore
... A455: NL01AK5776 | B455: LNG | C455: Oraya Gas India Pvt.Ltd. | D455: Ennore

Sheet Vehicle List
A1: VehicleNumber | B1: VehicleType | C1: Transporter | D1: GALocation
A2: KA01AL4119 | B2: LNG Tanker | C2: Kongunadu Roadlines | D2: Dahej
A3: KA01AL3719 | B3: LNG Tanker | C3: Kongunadu Roadlines | D3: Dahej
A4: TN87B6394 | B4: LNG Tanker | C4: Kongunadu Roadlines | D4: Ennore
A5: TN87B6483 | B5: LNG Tanker | C5: Kongunadu Roadlines | D5: Ennore
A6: TN87B7069 | B6: LNG Tanker | C6: Kongunadu Roadlines | D6: Ennore
A7: KA01AL6761 | B7: LNG Tanker | C7: Kongunadu Roadlines | D7: Dahej
A8: KA01AL7519 | B8: LNG Tanker | C8: Kongunadu Roadlines | D8: Ennore
A9: KA01AL9139 | B9: LNG Tanker | C9: Kongunadu Roadlines | D9: Ennore
A10: TN88H6575 | B10: LNG Tanker | C10: Kongunadu Roadlines | D10: Kochi
A11: TN88H6508 | B11: LNG Tanker | C11: Kongunadu Roadlines | D11: Kochi
A12: NL01AE4803 | B12: LNG Tanker | C12: Kongunadu Roadlines | D12: Ennore
... A455: NL01AK5776 | B455: LNG Tanker | C455: Oraya Gas India Pvt.Ltd. | D455: Ennore

Sheet Nearmiss
A1: Sr.No | B1: Date | C1: Observer | D1: Event Trigger Time | E1: Vehicle No | F1: Driver Name | G1: Driver ID | H1: GA | I1: Description
A2: 1 | B2: 45083 | C2: K.Gopinath | D2: 0.66597222 | E2: KL19M6769 | F2: AWDHESH KUMAR | G2: AGP/CNG/UHS/62 | H2: UHS | I2: Driver slow down when 1st pedestrian crossed and observed mirror
A3: =A2+1 -> 2 | B3: 45085 | C3: K.Gopinath | D3: 0.76111111 | E3: KA50B1300 | F3: Basavaraju | G3: AGP/CNG/MMC-016 | H3: MMC | I3: A car from left side of the road tries to move to right side of the road reutls in nearmiss with our MCV
A4: =A3+1 -> 3 | B4: 45117 | C4: K.Gopinath | D4: 0.92708333 | E4: KA50B0744 | F4: Mahendra TM | G4: AGP/CNG/MMC-010 | H4: MMC | I4: A car from left side of the road tries to move to right side of the road reutls in nearmiss with our MCV
A5: =A4+1 -> 4 | B5: 45126 | C5: K.Gopinath | D5: 0.32291667 | E5: KA50B1426 | F5: Umesh BE | G5: AGP/CHK-426 | H5: CHK | I5: A Two wheeler change lane from right to left suddenly
A6: =A5+1 -> 5 | B6: 45141 | C6: K.Gopinath | D6: 0.54166667 | E6: KL19M6407 | F6: NOUPHAL.A | G6: AGP/CNG/AKT/018 | H6: AKT | I6: Two wheeler from middle of the road tries to cross the road suddenly results in nearmiss with our MCV
A7: =A6+1 -> 6 | B7: 45143 | C7: K.Gopinath | D7: 0.29166667 | E7: KL09AV4329 | F7: unassigned | G7: unassigned | H7: AKT | I7: Two wheeler from middle of the road tries to cross the road suddenly results in nearmiss with our MCV
A8: =A7+1 -> 7 | B8: 45145 | C8: K.Gopinath | D8: 0.66527778 | E8: AP39UC4153 | F8: C Venkateshwarlu | G8: AGP/CNG/NEL /0670 | H8: Nellore | I8: A truck from left side of the road tries to move to right side of the road reutls in nearmiss with our MCV
A9: =A8+1 -> 8 | B9: 45150 | C9: K.Gopinath | D9: 0.70277778 | E9: KA50B1322 | F9: Vishwaradhya | G9: AGP/CNG/KV/023 | H9: KV | I9: Animal is standing in the middle of the road our MCV driver observed it and stops the vehicle
A10: =A9+1 -> 9 | B10: 45150 | C10: K.Gopinath | D10: 0.73680556 | E10: KA50B1427 | F10: KOTRESH | G10: AGP/CNG/BKR/01 | H10: BKR | I10: In a Two lane undivided road, A Vehicle from opposite side tries to overtake the other vehicle in same lane which results in nearmiss with our MCV. Our MCV driver was cautious and took slight left to avoid contact with that vehicle.
A11: =A10+1 -> 10 | B11: 45154 | C11: K.Gopinath | D11: 0.70555556 | E11: TN88J0417 | F11: V Thiruvengadam | G11: AGP/CNG/KANCHI/059 | H11: KAN | I11: In this video Person travelling in two wheeler not following the overtake procedure which results in Nearmiss (16:56:04)
A12: =A11+1 -> 11 | B12: 45154 | C12: K.Gopinath | D12: 0.70833333 | E12: KA50B1276 | F12: Lingashetty | G12: AGP/CNG/KV/011 | H12: KV | I12: Driver not following overtake procedure and there is no enough space after overtaking our MCV vehicle which results in Nearmiss with opposite Bike and Car and overspeeding violation found as per norms.
A13: =A12+1 -> 12 | B13: 45154 | C13: K.Gopinath | D13: 0.78888889 | E13: KA50B0743 | F13: SATHISH C S | G13: AGP/CNG/MMC/005 | H13: MMC | I13: Car from opposite side waiting in the middle of the road to cross the road. Our Driver observed and slow downs the vehicle & took a slight left to avoid contact with that vehicle which results in Nearmiss Event (18:56:52)
A14: =A13+1 -> 13 | B14: 45154 | C14: K.Gopinath | D14: 0.83055556 | E14: RJ14GP5033 | F14: Vikram Singh | G14: AGP/CNG/BJJ/126 | H14: BJJ | I14: Nearmiss Reported at 19:56:00 A Car from middle of the road makes a U turn suddenly Our Driver observed and slows down the vehicle.
... A23: =A22+1 -> 22 | B23: 45176 | C23: K.Gopinath | D23: 0.70416667 | E23: KA01AN0972 | F23: Balanji MM | G23: AGP/CNG/KOL/012 | H23: Kolar | I23: Bike Rider from opposite lane of the road tries to cross the road suddenly our MCV driver observed it and took slight right to avoid collision with the bike rider.
A24: =A23+1 -> 23 | B24: 45181 | C24: Deepak Pathak | D24: 0.52708333 | E24: KL19M6407 | I24: Near miss observed at 12 second , Driver violating the lane discipline and lane marking, trying to overtake third party vehicle while there is other vehicle coming from opposite side. Please advise the driver to follow lane discipline, lane marking and always follow the safe overtaking process.
A25: =A24+1 -> 24 | B25: 45185 | C25: K.Gopinath | D25: 0.72291667 | E25: KA50B1301 | F25: Vijendra | G25: AGP/CNG/CHK-428 | H25: CHK | I25: Nearmiss Reported (17:21:15) A car from opposite lane suddenly tries to cross the road without any indication. our MCV Driver Observed the car and slow down the vehicle to avoid Collison with that car.
A26: =A25+1 -> 25 | B26: 45188 | C26: Rmachandran | D26: 0.67083333 | E26: KA50B1424 | F26: Hanamanth | G26: AGP/CNG/KV/0632 | H26: KV | I26: Today at 16:27hrs Third-party driver catch hold of this MCV driver and was questioning him for his bad behaviour. Following are the reason which was done by our MCV driver on other third-party driver to get in ROAD RAGE & involve in near-miss incident:-Rase driving wrong overtaking
A27: =A26+1 -> 26 | B27: 23-9-23 | C27: Deepak Pathak | D27: 0.53472222 | E27: NL01AE4803 | F27: Girijesh kumar singh | G27: AGP/LNG/139 | H27: Dahej | I27: Vehicle was standing in Traffic Jam, when Tanker started moving other third-party vehicle was overtaking our Tanker from wrong side and in resulting coming in blind sport of tanker/driver, At that time Co-driver need to be attentive and use hand signal from his side to avoid any incident which is also provide in the training but instead he was on phone. Kindly educated the driver accordingly.
A28: =A27+1 -> 27 | B28: 25-09-23 | C28: Deepak Pathak | D28: 0.65138889 | E28: KL09AV4263 | F28: SAJILAL | G28: AGP/CNG/AKT/073 | H28: AKT | I28: Driver was doing Road rage with rear vehicle & To be overtaken process not followed
A29: 28 | B29: 45205 | C29: K.Gopinath | D29: 0.26388889 | E29: RJ14GP2189 | F29: OM PRAKASH-I | G29: AGP/CNG/BJJ/040 | H29: BJJ | I29: Nearmiss Reported 06:20Am Our MCV overtakes a third party vehicle suddenly Pedestrian cross the opposite side of the road results in nearmiss without Collison with pedestrain (Refer 00:50)
A30: 29 | B30: 45211 | C30: K.Gopinath | D30: 0.67708333 | E30: TN87B6382 | F30: Virendra Kumar Yadav | G30: AGP/LNG/255 | H30: Ennore | I30: Nearmiss Reported at 16:15 Two Wheeler from opposite side tries to cross other side of the road Our LNG Tanker driver observed it and slow downs the vehicle (Ref 00:12)
A31: 30 | B31: 45203 | C31: Harish | D31: 0.74583333 | E31: KA01AM6187 | H31: MMC | I31: Third party vehicle "Car" suddenly over takes the other vehicle without any indication , Our MCV driver Observed and Applied sudden brake to avoid collision with that vehicle.
A32: 31 | B32: 45240 | C32: Vijayan G | D32: 0.83333333 | E32: KL19M6715 | F32: Suresh kumar | G32: AGP/CNG/NEL/0673 | H32: Vellore | I32: Driver was aggressively took right from left lane to middle lane without any indication
A33: 32 | B33: 45250 | C33: Deepak Pathak | D33: 0.58402778 | E33: TN88J2175 | F33: Bhairo Nath Yadav | G33: AGP/LNG/269 | H33: Dahej | I33: Vehicle was running on 2nd lane and driver was in distraction, so did not observed Front moving bus stopped suddenly to deboard passengers, driver was maintaining the safe distance and steered the tanker towards right lane and no incident happened. Co-driver was on phone and not guided main driver. Please advice the driver always keep his eye on road and not involve in distraction while driving and such situations co-driver need to alert and guide the main driver
A34: 33 | B34: 45263 | C34: K.Gopinath | D34: 0.72569444 | E34: KA01AN7747 | F34: Srikanth | G34: AGP/CHK-409 | H34: CHK | I34: A car from service road takes a left with Indication to join the Bypass Road but suddenly other third party vehicle from same road tries to overtake the car without indication so the car suddenly stopped the vehicle. Our MCV Driver observed it and applied a sudden brake to avoid collision with the car.
A35: 34 | B35: 45275 | C35: Deepak Pathak | D35: 0.55694444 | E35: KA01AL3719 | F35: Rajkumar Yadav | G35: AGP/LNG/291 | H35: Dahej | I35: Vehicle was negotiating the Roundabout with Haphazard movement of other road users. As driver moved the tanker from left side to right side to negotiate the round about. A Third party crusher was on his lane at right side of the tanker, while making the turn our driver did not signal the third party crusher driver & did not judge the turning radius of the vehicle. Since third party crusher driver stopped his vehicle, incident avoided. Please educated the driver about Right of way at Round about and always judge the turning radius of the vehicle while taking turn at round about
A36: 35 | B36: 45282 | C36: Deepak Pathak | D36: 0.46597222 | E36: TN88H2182 | F36: Thirunavvukarasu | G36: AGP/CNG/NEL/0668 | H36: ANK | I36: MCV was crossing an intersection with Haphazard movement of other road users, at the same time suddenly a bike rider came Infront of the vehicle through Gap in median from opposite side and crossed the road towards LHS intersection, thereby Near-miss reported. As MCV was at intersection driver could have decrease the speed of the vehicle in this case. And @11:12:20hrs MCV was negotiating Roundabout, a pedestrian was crossing the road, MCV steered the vehicle towards right and moved, which caused an auto-rickshaw and other road users at right side of the MCV forced to stop suddenly leading a Near-miss. MCV driver could have slow down before negotiating round about and stopped to allowing pedestrian to cross the road in this case. Please educate the driver about Right of way at intersection/ round-about and be-aware & cautious about the Haphazard movement of other road users.
A37: 36 | B37: 45286 | C37: Deepak Pathak | D37: 0.60833333 | E37: KA01AN7742 | F37: Vijendra | G37: AGP/CNG/CHK-428 | H37: CHK | I37: Vehicle is running at Single Undivided road with Haphazard movement of other road users. @14:36:01hrs one Auto that was trying to overtake other vehicle came in front of our MCV, incident avoided by MCV driver. At the same time one lady passenger suddenly came Infront of moving bus and auto took U-turn in-front of the bus. (Recorded in rear camera).@14:36:17hrs pedestrian crossing the road suddenly running in-front of the bus. (Recorded in rear camera). @14:36:32 Black car tried to move to other side of road from constructed area. MCV driver noticed well in advance and stopped the vehicle thereby incident avoided. Same situation happened with bus with sedan car which was trying maneuvering but bus driver avoided incident (recorded in rear camera)
A38: =A37+1 -> 37 | B38: 45293 | C38: Deepak Pathak | D38: 0.60902778 | E38: KA01AP0284 | F38: Jayashankar Murthy BS | G38: AGP/CNG/CHK-431 | H38: CHK | I38: Vehicle was running on single undivided dual carriage road and trying to overtake a tractor trolly. As driver start the overtaking, from opposite side an auto came and driver have to stop the overtaking. Kindly educate the drivers on correct method of overtaking (MSM rule), and not to overtake on single undivided dual carriage road without confirming space cushion.
A39: =A38+1 -> 38 | B39: 45330 | C39: Deepak Pathak | D39: 0.51041667 | E39: KA01AM0219 | F39: Ravishankar | G39: AGP/LNG/206 | H39: Kochi | I39: @12:15:39hrs:- vehicle was standing at unsafe parking space (left side of the road) and driver was speaking over phone after finishing, while merging the vehicle on road, driver didn't observe the mirror and rear traffic. As third-party Auto driver observed the tanker and stopped his vehicle, thereby incident avoided. Please educate the driver to always use mirror when merging into traffic from standing position. And not to park his vehicle at unsafe parking place (left side of the road).
A40: 39 | B40: 45351 | C40: Deepak Pathak | D40: 0.5625 | E40: KL07DC0563 | F40: PRAMOD K S | G40: AGP/CNG/AKT/036 | H40: AKT | I40: In a single undivided road, driver overtook the front moving third party open body truck, at the same time one bike rider coming from opposite direction didn't had space, then driver steering suddenly towards left, without completing the overtaking. Third party truck driver slow down then steered to his left and avoided incident. There was no space between two vehicles and MSM rule was not adhered. Kindly educate the driver to follow the MSM rule while overtaking, no overtaking on single lane undivided dual carriage road, judge whether overtaking is required in this condition and not to overtake any vehicle if front on coming traffic is available.
A41: =A40+1 -> 40 | B41: 45351 | C41: K.Gopinath | D41: 0.71319444 | E41: GJ16AW1575 | F41: Kamal Dev | G41: AGP/LNG/163 | H41: Ennore | I41: Near miss observed :- @17:07:17hrs, Tanker was running at 2 way lane road and there was gap in median, Few bike riders was trying to cross the intersection as tanker driver seen, then he stopped the vehicle and let them cross (Refer video -1). After few meter one more gap in median was there on the same, one bike rider cross the road suddenly and tanker driver didn't observed and didn't slow down his vehicle. As bike driver was too fast so incident avoided. (Refer video-2) observation :- At that time 2nd driver was on phone, 1st driver didn't noticed bike rider. Kindly educate the driver on always to be cautious at gap in median for Haphazard movement and educate codrivers need to assist the main driver at this type of road, traffic condition by giving hand single to the traffic for smooth running and even alert the main driver to stop if required.
A42: 41 | B42: 45354 | C42: V. Praveen Kumar | D42: 0.475 | E42: KA01AM5285 | F42: KIRAN KUMAR | G42: AGP/CNG/BKR/06 | H42: BKR | I42: vehicle was coming out from the safe parking place ( MS Koppal) , when vehicle was merging from service road to main road one bike ride was coming from wrong side. But due to search of something in the pocket the driver left both hand of the steering and also not looking towards the road. Vehicle start drifting towards the bike rider at the last second driver steer the vehicle towards opposite side and incident avoided.
A43: =A42+1 -> 42 | B43: 45356 | C43: K.Gopinath | D43: 0.325 | E43: RJ19GH8324 | F43: Man Singh | G43: AGP/CNG/BJJ/030 | H43: BJJ | I43: Near-miss observed @07:48:56hrs: A third party passenger car was parked on left side of the road, MCV driver steered the vehicle due to which MCV vehicle was very close to opposite on-coming vehicle and incident was avoided. Kindly instruct the driver to maintain minimum clearance with opposite vehicle on double lane road
A44: =A43+1 -> 43 | B44: 45360 | C44: Harish | D44: 0.98077546 | E44: KA01AN2554 | F44: K ACHARI | G44: AGP/CNG/ANK/5050 | H44: ANK | I44: Driver was driving on a single lane undivided construction road. At around 23:32:19hrs front running 3rd party vehicle Mahindra camper over loaded vehicle driver steered the vehicle towards his right side due to unbalanced condition and stopped, at the same time Innova with siren following our MCV. In this condition MCV steered the vehicle towards left side and negotiating through a less space on mud area part available at road shoulder and crossed the location, then siren Innova car overtook from right side. Luckily incident avoided by the MCV driver. To give way for Innova siren car, need not to cross the unsafe area and provide way but we'll in advance slow down the vehicle and pass the car and after clearance MCV should have moved.
A45: =A44+1 -> 44 | B45: 45364 | C45: K.Gopinath | D45: 0.72361111 | E45: RJ19GH7454 | F45: Bhanwar Dan | G45: AGP/CNG/BJJ/123 | H45: BJJ | I45: RJ19GH7454 - Near-miss cases reported while monitoring Location - BJJ and time 17:22:30 hrs :- MCV was moving on right side lane inside City location and following Near-miss reported 1) Bike moved from right side to left side in front of our MCV 2) Passenger Auto moved from right side to left side in-front of commercial auto blue colour running infront of our MCV recorded in camera (Not related to MCV but for knowledge purpose) 3) Bike moved from left side to right side at Gap in median and suddenly moved in front of tractor which was taking u-turn, tractor stopped and avoided incident. Recorded in Right side camera. Kindly share the above Near-miss and educate on Slowdown at intersection, give way for Small vehicle road users (Car, Bike) and to right side traffic vehicles.
A46: =A45+1 -> 45 | B46: 45364 | C46: K.Gopinath | D46: 0.76527778 | E46: TN88J2146 | F46: Indresh Kumar Tiwari | G46: AGP/LNG/298 | H46: Dahej | I46: TN88J2146 Near-miss case and Good observation noticed while monitoring 18:22:27 hrs :- Tanker was moving on its left side lane on 4 lane dual carriage divided road and following Near-miss and Good Observation noticed:- Good Observation: Tanker driver was driving on left side of the lane, speed with respect to road/traffic condition, observing mirrors regularly, steering position 9:3, avoided incident with speeded third party tanker which overtook and came on its lane, also incident avoided with scooty rider which moved suddenly from its location, left side of the tanker. Near-miss: Tanker driver slow down the vehicle so that incident avoided with scooty and he tried to move suddenly from stationary position. Kindly share to other drivers on Good observations to adopt while Driving (Expect the Unexpected).
A47: =A46+1 -> 46 | B47: 45366 | C47: Vijayan G | D47: 0.54375 | E47: KA01AM4883 | F47: Mahesh t | G47: AGP/LNG/110 | H47: Ennore | I47: Tanker was taking right turn for weighment through Gap in median from its lane, at that time one third party truck was standing there, our driver did not judge the turning radius while making the turn and 2nd driver who was observing and guiding the 1st driver, saw the gap was less then informed the 1st driver to stop the vehicle, thereby incident avoided.
A49: 47 | B49: 45360 | C49: Harish | D49: 0.47569444 | E49: KA01AM4286 | F49: Dileep B J | G49: AGP/LNG/301 | H49: Kochi | I49: Our Tanker was moving on its left side lane at the same time opposite third-party vehicle car without any intimation crossing the road at the same time bus from opposite right side lane, which is a traffic area and there may be sudden haphazard movements. But Second driver is sitting on co-driver seat with on phone in this traffic road condition, without guiding driver. Train the drivers accordingly to guide the main driver or let them sleep on their berth.
...

Sheet EMERGENCY NO 
A1: S.No | B1: GA NAME | C1: EMERGENCY NO | D1: GA Control Center Contacts
A2: 1 | B2: AKT | C2: 7358278111 | D2: 7358278111
A4: 2 | B4: ANK | C4: 8056901333 | D4: 8056901333
A5: 3 | B5: BJJ | C5: 7358067890 | D5: 9773341800
A6: 4 | B6: BKR | C6: 8220584222 (R) | D6: 8220584222 (R)
C7: 8925818562 (K)
C8: 8925818561 (B)
A9: 5 | B9: CHK | C9: 8220539222 | D9: 8220539222
A10: 6 | B10: CVK-C | C10: 9677110001 | D10: 9677110001
A11: 7 | B11: CVK-VK | C11: 8056847333 | D11: 8056847333/9123555943
A12: 8 | B12: KAN | C12: 8056586333 | D12: 8056586333
A13: 9 | B13: KV | C13: 8220463222 | D13: 8472200673
A14: 10 | B14: MMC | C14: 7358550022 | D14: 7358550022/8925818560
A16: 11 | B16: NLR | C16: 7200108123 | D16: 7200108123
A17: 12 | B17: RMN | C17: 7358253999 | D17: 7358253999
A18: 13 | B18: UHS | C18: 8754106222 | D18: 8754106222

Sheet TG Contact
A1: S.No | B1: Location | C1: Journey Manager | D1: Mobile | E1: Mail | F1: Reporting | G1: GA Head | H1: Marketing
A2: 1 | B2: Bhopal | C2: Yogesh | D2: 7045073822 & 97981 68044 & 88606 76337 | E2: Yogesh.bharmal@think-gas.com | F2: Piyush.patel | G2: DS Durgesh
A3: 2 | B3: Bhagpat | C3: Vijay &Akhil | D3: 7310505464, 9012350009 | E3: Vijay.kumar@think-gas.com &Akhil.arora@think-gas.com | F3: Parush.kohli | G3: Vikalp Shukla
A4: 3 | B4: Beguserai | C4: Rakesh | D4: 9984727872 | E4: Rakesh.singh@think-gas.com | G4: Vijay Tiwari
A5: 4 | B5: Ludhiana | C5: Gurinder & Dawinder | D5: 8699559500 , 8194876146 | E5: Gurinder.verma@think-gas.com, Dawinder.singh@think-gas.com | F5: Money sabharwal | G5: Piyush bodhana
A6: 5 | B6: Jalandar | C6: Gurinder & Dawinder | D6: 8699559500 , 8194876146 | E6: Gurinder.verma@think-gas.com, Dawinder.singh@think-gas.com | F6: Gaurav sabhawaral | G6: Vineeth kumar | H6: Prabhat.Das@think-gas.com Money.Sabharwal@think-gas.com Radharaman.gupta@think-gas.com
A7: 6 | B7: Shivpuri | C7: Yogesh | D7: 7045073822 & 97981 68044 | E7: Yogesh.bharmal@think-gas.com | F7: Tushar bari | G7: Priyank (Marketing),DS Durgesh
A8: 7 | B8: Himachal | C8: Gurinder & Dawinder | D8: 8699559500 , 8194876146 | E8: Gurinder.verma@think-gas.com, Dawinder.singh@think-gas.com
E10: Row Labels | F10: Type of Station
E11: Gopal Krishna Sarangpur | F11: DS
E12: Hakimi petroleum | F12: DS
E13: Volvo Eicher | F13: DS
E14: Gokul fuel services | F14: DS
E15: Kavi filling station | F15: DS
E16: Renuka filling station | F16: DS
E17: Jagdish filling Pachore | F17: DS
E18: LC Berasia | F18: DS
E19: SHREERAM AUTO IOCL | F19: DS
