Workbook
Name Slicer_Violations_Vehicle_Day: #N/A
Name Slicer_Violations_Vehicle_Day1: #N/A

Sheet Mail Summ
A1: GA | B1: Location | C1: No of vehicles in Operation | D1: Camera Fitted | E1: Camera not Fitted | F1: AI camera working ( 23 Feb ) | G1: ='Mar Day Summ'!B1 -> 46098 | H1: ='Mar Mon Summ'!B1 -> 46082 | I1: Violations/Vehicle/Day
A2: AKT | B2: Alapuza, Trivandrum | C2: 28 | D2: 28 | E2: 0 | F2: 24 | G2: ='Mar Day Summ'!L3 -> 2 | H2: ='Mar Mon Summ'!L3 -> 28 | I2: =IFERROR(H2/C2/DAY($G$1),0) -> 0.058823529
A3: ANK | B3: Ananthapur, Kadappa | C3: 11 | D3: 11 | E3: 0 | F3: 10 | G3: ='Mar Day Summ'!L4 -> 0 | H3: ='Mar Mon Summ'!L4 -> 5 | I3: =IFERROR(H3/C3/DAY($G$1),0) -> 0.026737968
A4: Baghpat | B4: Baghpat | C4: 20 | D4: 20 | E4: 0 | F4: 0 | G4: ='Mar Day Summ'!L5 -> 1 | H4: ='Mar Mon Summ'!L5 -> 4 | I4: =IFERROR(H4/C4/DAY($G$1),0) -> 0.011764706
A5: Begusarai | B5: Begusarai | C5: 4 | D5: 4 | E5: 0 | F5: 0 | G5: ='Mar Day Summ'!L6 -> 0 | H5: ='Mar Mon Summ'!L6 -> 0 | I5: =IFERROR(H5/C5/DAY($G$1),0) -> 0
A6: Bhopal | B6: Bhopal / Shivpuri | C6: 44 | D6: 44 | E6: 0 | F6: 10 | G6: ='Mar Day Summ'!L7 -> 1 | H6: ='Mar Mon Summ'!L7 -> 14 | I6: =IFERROR(H6/C6/DAY($G$1),0) -> 0.018716578
A7: BJJ | B7: Jodhpur | C7: 51 | D7: 46 | E7: 5 | F7: 42 | G7: ='Mar Day Summ'!L8 -> 1 | H7: ='Mar Mon Summ'!L8 -> 11 | I7: =IFERROR(H7/C7/DAY($G$1),0) -> 0.012687428
A8: BKR | B8: Bagalkot, Raichur | C8: 11 | D8: 11 | E8: 0 | F8: 11 | G8: ='Mar Day Summ'!L9 -> 0 | H8: ='Mar Mon Summ'!L9 -> 1 | I8: =IFERROR(H8/C8/DAY($G$1),0) -> 0.0053475936
A9: Chittoor | B9: Tirupathi | C9: 14 | D9: 11 | E9: 3 | F9: 10 | G9: ='Mar Day Summ'!L10 -> 0 | H9: ='Mar Mon Summ'!L10 -> 0 | I9: =IFERROR(H9/C9/DAY($G$1),0) -> 0
A10: CHK | B10: Hassan | C10: 13 | D10: 13 | E10: 0 | F10: 8 | G10: ='Mar Day Summ'!L11 -> 0 | H10: ='Mar Mon Summ'!L11 -> 2 | I10: =IFERROR(H10/C10/DAY($G$1),0) -> 0.0090497738
A11: Dahej | B11: Dahej | C11: 25 | D11: 22 | E11: 3 | F11: 22 | G11: ='Mar Day Summ'!L12 -> 1 | H11: ='Mar Mon Summ'!L12 -> 13 | I11: =IFERROR(H11/C11/DAY($G$1),0) -> 0.030588235
A12: Ennore | B12: Ennore/Dabhol | C12: 23 | D12: 23 | E12: 0 | F12: 23 | G12: ='Mar Day Summ'!L13 -> 2 | H12: ='Mar Mon Summ'!L13 -> 17 | I12: =IFERROR(H12/C12/DAY($G$1),0) -> 0.043478261
A13: Hazira | B13: Hazira | C13: 1 | D13: 1 | E13: 0 | F13: 1 | G13: ='Mar Day Summ'!L14 -> 0 | H13: ='Mar Mon Summ'!L14 -> 1 | I13: =IFERROR(H13/C13/DAY($G$1),0) -> 0.058823529
... A23: Vellore | B23: Vellore | C23: 13 | D23: 12 | E23: 1 | F23: 9 | G23: ='Mar Day Summ'!L24 -> 0 | H23: ='Mar Mon Summ'!L24 -> 3 | I23: =IFERROR(H23/C23/DAY($G$1),0) -> 0.013574661
A24: Total | C24: =SUM(C2:C23) -> 449 | D24: =SUM(D2:D23) -> 429 | E24: =SUM(E2:E23) -> 20 | F24: =SUM(F2:F23) -> 301 | G24: =SUM(G2:G23) -> 12 | H24: =SUM(H2:H23) -> 159 | I24: =IFERROR(H24/C24/DAY($G$1),0) -> 0.020830604

Sheet Mail Summ2
A1: Highest Violations Contributor GA/Terminal | E1: Best Performer GA/Terminal
A3: GA | B3: Violations/Vehicle/Day | C3: Highest Violation Contributer | E3: Row Labels | F3: Violations/Vehicle/Day | G3: Best performer
A4: Kolar | B4: 0.14705882 | C4: Month | D4: =MAX('Mail Summ'!I2:I23) -> 0.14705882 | E4: Chittoor | F4: 0 | G4: Month | H4: =MIN('Mail Summ'!I2:I23) -> 0
A5: AKT | B5: 0.058823529 | C5: GA | D5: {=_xlfn.TEXTJOIN(", ",TRUE,IF('Mail Summ'!I2:I23=D4,'Mail Summ'!A2:A23,""))} -> Kolar | E5: Begusarai | F5: 0 | G5: GA | H5: {=_xlfn.TEXTJOIN(", ",TRUE,IF('Mail Summ'!I2:I23='Mail Summ2'!H4,'Mail Summ'!A2:A23,""))} -> Begusarai, Chittoor, RMN
A6: Hazira | B6: 0.058823529 | C6: Day | D6: =MAX('Mail Summ'!G2:G23) -> 2 | E6: RMN | F6: 0 | G6: Day | H6: =MIN('Mail Summ'!G2:G23) -> 0
A7: Kochi | B7: 0.052631579 | C7: GA | D7: {=_xlfn.TEXTJOIN(", ",TRUE,IF('Mail Summ'!G2:G23=D6,'Mail Summ'!A2:A23,""))} -> AKT, Ennore, KNCP | E7: UHS | F7: 0.0024509804 | G7: GA | H7: {=_xlfn.TEXTJOIN(", ",TRUE,IF('Mail Summ'!G2:G23=H6,'Mail Summ'!A2:A23,""))} -> ANK, Begusarai, BKR, Chittoor, CHK, Hazira, Jalandhar, KNV, Kolar, MMC, Nellore, RMN, Vellore
A8: Ennore | B8: 0.043478261 | E8: BKR | F8: 0.0053475936
A9: Dahej | B9: 0.030588235 | E9: Nellore | F9: 0.0053475936
A10: ANK | B10: 0.026737968 | E10: KNV | F10: 0.0065359477
A11: Jalandhar | B11: 0.021116139 | E11: MMC | F11: 0.0078431373
A12: Bhopal | B12: 0.018716578 | E12: CHK | F12: 0.0090497738
A13: KNCP | B13: 0.018255578 | E13: Baghpat | F13: 0.011764706
A14: Vellore | B14: 0.013574661 | E14: BJJ | F14: 0.012687428
A15: Grand Total | B15: 0.14705882 | E15: Grand Total | F15: 0.06102716

Sheet Mar Day Summ
A1: Report For Date | B1: =MAX('Soruce file '!B:B)-1 -> 46098
A2: Location | B2: Mobile Usage | C2: No Seatbelt | D2: Yawning | E2: Driver Fatigue | F2: Harsh Braking | G2: Over speed | H2: Sudden Acceleration | I2: Camera Anomaly | J2: Continuous Driving | K2: Night Driving | L2: Total
A3: AKT | B3: =IFERROR(SUMIFS(INDEX('Soruce file '!$A:$Z, 0, MATCH("Mobile Usage", 'Soruce file '!$1:$1, 0)), INDEX('Soruce file '!$A:$Z, 0, MATCH("Date", 'Soruce file '!$1:$1, 0)), $B$1, INDEX('Soruce file '!$A:$Z, 0, MATCH("GA*", 'Soruce file '!$1:$1, 0)), $A3), 0) -> 1 | C3: =IFERROR(SUMIFS(INDEX('Soruce file '!$A:$Z, 0, MATCH("No Seatbelt", 'Soruce file '!$1:$1, 0)), INDEX('Soruce file '!$A:$Z, 0, MATCH("Date", 'Soruce file '!$1:$1, 0)), $B$1, INDEX('Soruce file '!$A:$Z, 0, MATCH("GA*", 'Soruce file '!$1:$1, 0)), $A3), 0) -> 0 | D3: =IFERROR(SUMIFS(INDEX('Soruce file '!$A:$Z, 0, MATCH("Yawning", 'Soruce file '!$1:$1, 0)), INDEX('Soruce file '!$A:$Z, 0, MATCH("Date", 'Soruce file '!$1:$1, 0)), $B$1, INDEX('Soruce file '!$A:$Z, 0, MATCH("GA*", 'Soruce file '!$1:$1, 0)), $A3), 0) -> 0 | E3: =IFERROR(SUMIFS(INDEX('Soruce file '!$A:$Z, 0, MATCH("Fatigue", 'Soruce file '!$1:$1, 0)), INDEX('Soruce file '!$A:$Z, 0, MATCH("Date", 'Soruce file '!$1:$1, 0)), $B$1, INDEX('Soruce file '!$A:$Z, 0, MATCH("GA*", 'Soruce file '!$1:$1, 0)), $A3), 0) -> 0 | F3: =IFERROR(SUMIFS(INDEX('Soruce file '!$A:$Z, 0, MATCH("Harsh Braking", 'Soruce file '!$1:$1, 0)), INDEX('Soruce file '!$A:$Z, 0, MATCH("Date", 'Soruce file '!$1:$1, 0)), $B$1, INDEX('Soruce file '!$A:$Z, 0, MATCH("GA*", 'Soruce file '!$1:$1, 0)), $A3), 0) -> 0 | G3: =IFERROR(SUMIFS(INDEX('Soruce file '!$A:$Z, 0, MATCH("Overspeed", 'Soruce file '!$1:$1, 0)), INDEX('Soruce file '!$A:$Z, 0, MATCH("Date", 'Soruce file '!$1:$1, 0)), $B$1, INDEX('Soruce file '!$A:$Z, 0, MATCH("GA*", 'Soruce file '!$1:$1, 0)), $A3), 0) -> 1 | H3: =IFERROR(SUMIFS(INDEX('Soruce file '!$A:$Z, 0, MATCH("Sudden Acceleration", 'Soruce file '!$1:$1, 0)), INDEX('Soruce file '!$A:$Z, 0, MATCH("Date", 'Soruce file '!$1:$1, 0)), $B$1, INDEX('Soruce file '!$A:$Z, 0, MATCH("GA*", 'Soruce file '!$1:$1, 0)), $A3), 0) -> 0 | I3: =IFERROR(SUMIFS(INDEX('Soruce file '!$A:$Z, 0, MATCH("Camera Anomaly", 'Soruce file '!$1:$1, 0)), INDEX('Soruce file '!$A:$Z, 0, MATCH("Date", 'Soruce file '!$1:$1, 0)), $B$1, INDEX('Soruce file '!$A:$Z, 0, MATCH("GA*", 'Soruce file '!$1:$1, 0)), $A3), 0) -> 0 | J3: =IFERROR(SUMIFS(INDEX('Soruce file '!$A:$Z, 0, MATCH("CD", 'Soruce file '!$1:$1, 0)), INDEX('Soruce file '!$A:$Z, 0, MATCH("Date", 'Soruce file '!$1:$1, 0)), $B$1, INDEX('Soruce file '!$A:$Z, 0, MATCH("GA*", 'Soruce file '!$1:$1, 0)), $A3), 0) -> 0 | K3: =IFERROR(SUMIFS(INDEX('Soruce file '!$A:$Z, 0, MATCH("Night Driving", 'Soruce file '!$1:$1, 0)), INDEX('Soruce file '!$A:$Z, 0, MATCH("Date", 'Soruce file '!$1:$1, 0)), $B$1, INDEX('Soruce file '!$A:$Z, 0, MATCH("GA*", 'Soruce file '!$1:$1, 0)), $A3), 0) -> 0 | L3: =SUM(B3:K3) -> 2
A4: ANK | B4: =IFERROR(SUMIFS(INDEX('Soruce file '!$A:$Z, 0, MATCH("Mobile Usage", 'Soruce file '!$1:$1, 0)), INDEX('Soruce file '!$A:$Z, 0, MATCH("Date", 'Soruce file '!$1:$1, 0)), $B$1, INDEX('Soruce file '!$A:$Z, 0, MATCH("GA*", 'Soruce file '!$1:$1, 0)), $A4), 0) -> 0 | C4: =IFERROR(SUMIFS(INDEX('Soruce file '!$A:$Z, 0, MATCH("No Seatbelt", 'Soruce file '!$1:$1, 0)), INDEX('Soruce file '!$A:$Z, 0, MATCH("Date", 'Soruce file '!$1:$1, 0)), $B$1, INDEX('Soruce file '!$A:$Z, 0, MATCH("GA*", 'Soruce file '!$1:$1, 0)), $A4), 0) -> 0 | D4: =IFERROR(SUMIFS(INDEX('Soruce file '!$A:$Z, 0, MATCH("Yawning", 'Soruce file '!$1:$1, 0)), INDEX('Soruce file '!$A:$Z, 0, MATCH("Date", 'Soruce file '!$1:$1, 0)), $B$1, INDEX('Soruce file '!$A:$Z, 0, MATCH("GA*", 'Soruce file '!$1:$1, 0)), $A4), 0) -> 0 | E4: =IFERROR(SUMIFS(INDEX('Soruce file '!$A:$Z, 0, MATCH("Fatigue", 'Soruce file '!$1:$1, 0)), INDEX('Soruce file '!$A:$Z, 0, MATCH("Date", 'Soruce file '!$1:$1, 0)), $B$1, INDEX('Soruce file '!$A:$Z, 0, MATCH("GA*", 'Soruce file '!$1:$1, 0)), $A4), 0) -> 0 | F4: =IFERROR(SUMIFS(INDEX('Soruce file '!$A:$Z, 0, MATCH("Harsh Braking", 'Soruce file '!$1:$1, 0)), INDEX('Soruce file '!$A:$Z, 0, MATCH("Date", 'Soruce file '!$1:$1, 0)), $B$1, INDEX('Soruce file '!$A:$Z, 0, MATCH("GA*", 'Soruce file '!$1:$1, 0)), $A4), 0) -> 0 | G4: =IFERROR(SUMIFS(INDEX('Soruce file '!$A:$Z, 0, MATCH("Overspeed", 'Soruce file '!$1:$1, 0)), INDEX('Soruce file '!$A:$Z, 0, MATCH("Date", 'Soruce file '!$1:$1, 0)), $B$1, INDEX('Soruce file '!$A:$Z, 0, MATCH("GA*", 'Soruce file '!$1:$1, 0)), $A4), 0) -> 0 | H4: =IFERROR(SUMIFS(INDEX('Soruce file '!$A:$Z, 0, MATCH("Sudden Acceleration", 'Soruce file '!$1:$1, 0)), INDEX('Soruce file '!$A:$Z, 0, MATCH("Date", 'Soruce file '!$1:$1, 0)), $B$1, INDEX('Soruce file '!$A:$Z, 0, MATCH("GA*", 'Soruce file '!$1:$1, 0)), $A4), 0) -> 0 | I4: =IFERROR(SUMIFS(INDEX('Soruce file '!$A:$Z, 0, MATCH("Camera Anomaly", 'Soruce file '!$1:$1, 0)), INDEX('Soruce file '!$A:$Z, 0, MATCH("Date", 'Soruce file '!$1:$1, 0)), $B$1, INDEX('Soruce file '!$A:$Z, 0, MATCH("GA*", 'Soruce file '!$1:$1, 0)), $A4), 0) -> 0 | J4: =IFERROR(SUMIFS(INDEX('Soruce file '!$A:$Z, 0, MATCH("CD", 'Soruce file '!$1:$1, 0)), INDEX('Soruce file '!$A:$Z, 0, MATCH("Date", 'Soruce file '!$1:$1, 0)), $B$1, INDEX('Soruce file '!$A:$Z, 0, MATCH("GA*", 'Soruce file '!$1:$1, 0)), $A4), 0) -> 0 | K4: =IFERROR(SUMIFS(INDEX('Soruce file '!$A:$Z, 0, MATCH("Night Driving", 'Soruce file '!$1:$1, 0)), INDEX('Soruce file '!$A:$Z, 0, MATCH("Date", 'Soruce file '!$1:$1, 0)), $B$1, INDEX('Soruce file '!$A:$Z, 0, MATCH("GA*", 'Soruce file '!$1:$1, 0)), $A4), 0) -> 0 | L4: =SUM(B4:K4) -> 0
A5: Baghpat | B5: =IFERROR(SUMIFS(INDEX('Soruce file '!$A:$Z, 0, MATCH("Mobile Usage", 'Soruce file '!$1:$1, 0)), INDEX('Soruce file '!$A:$Z, 0, MATCH("Date", 'Soruce file '!$1:$1, 0)), $B$1, INDEX('Soruce file '!$A:$Z, 0, MATCH("GA*", 'Soruce file '!$1:$1, 0)), $A5), 0) -> 0 | C5: =IFERROR(SUMIFS(INDEX('Soruce file '!$A:$Z, 0, MATCH("No Seatbelt", 'Soruce file '!$1:$1, 0)), INDEX('Soruce file '!$A:$Z, 0, MATCH("Date", 'Soruce file '!$1:$1, 0)), $B$1, INDEX('Soruce file '!$A:$Z, 0, MATCH("GA*", 'Soruce file '!$1:$1, 0)), $A5), 0) -> 1 | D5: =IFERROR(SUMIFS(INDEX('Soruce file '!$A:$Z, 0, MATCH("Yawning", 'Soruce file '!$1:$1, 0)), INDEX('Soruce file '!$A:$Z, 0, MATCH("Date", 'Soruce file '!$1:$1, 0)), $B$1, INDEX('Soruce file '!$A:$Z, 0, MATCH("GA*", 'Soruce file '!$1:$1, 0)), $A5), 0) -> 0 | E5: =IFERROR(SUMIFS(INDEX('Soruce file '!$A:$Z, 0, MATCH("Fatigue", 'Soruce file '!$1:$1, 0)), INDEX('Soruce file '!$A:$Z, 0, MATCH("Date", 'Soruce file '!$1:$1, 0)), $B$1, INDEX('Soruce file '!$A:$Z, 0, MATCH("GA*", 'Soruce file '!$1:$1, 0)), $A5), 0) -> 0 | F5: =IFERROR(SUMIFS(INDEX('Soruce file '!$A:$Z, 0, MATCH("Harsh Braking", 'Soruce file '!$1:$1, 0)), INDEX('Soruce file '!$A:$Z, 0, MATCH("Date", 'Soruce file '!$1:$1, 0)), $B$1, INDEX('Soruce file '!$A:$Z, 0, MATCH("GA*", 'Soruce file '!$1:$1, 0)), $A5), 0) -> 0 | G5: =IFERROR(SUMIFS(INDEX('Soruce file '!$A:$Z, 0, MATCH("Overspeed", 'Soruce file '!$1:$1, 0)), INDEX('Soruce file '!$A:$Z, 0, MATCH("Date", 'Soruce file '!$1:$1, 0)), $B$1, INDEX('Soruce file '!$A:$Z, 0, MATCH("GA*", 'Soruce file '!$1:$1, 0)), $A5), 0) -> 0 | H5: =IFERROR(SUMIFS(INDEX('Soruce file '!$A:$Z, 0, MATCH("Sudden Acceleration", 'Soruce file '!$1:$1, 0)), INDEX('Soruce file '!$A:$Z, 0, MATCH("Date", 'Soruce file '!$1:$1, 0)), $B$1, INDEX('Soruce file '!$A:$Z, 0, MATCH("GA*", 'Soruce file '!$1:$1, 0)), $A5), 0) -> 0 | I5: =IFERROR(SUMIFS(INDEX('Soruce file '!$A:$Z, 0, MATCH("Camera Anomaly", 'Soruce file '!$1:$1, 0)), INDEX('Soruce file '!$A:$Z, 0, MATCH("Date", 'Soruce file '!$1:$1, 0)), $B$1, INDEX('Soruce file '!$A:$Z, 0, MATCH("GA*", 'Soruce file '!$1:$1, 0)), $A5), 0) -> 0 | J5: =IFERROR(SUMIFS(INDEX('Soruce file '!$A:$Z, 0, MATCH("CD", 'Soruce file '!$1:$1, 0)), INDEX('Soruce file '!$A:$Z, 0, MATCH("Date", 'Soruce file '!$1:$1, 0)), $B$1, INDEX('Soruce file '!$A:$Z, 0, MATCH("GA*", 'Soruce file '!$1:$1, 0)), $A5), 0) -> 0 | K5: =IFERROR(SUMIFS(INDEX('Soruce file '!$A:$Z, 0, MATCH("Night Driving", 'Soruce file '!$1:$1, 0)), INDEX('Soruce file '!$A:$Z, 0, MATCH("Date", 'Soruce file '!$1:$1, 0)), $B$1, INDEX('Soruce file '!$A:$Z, 0, MATCH("GA*", 'Soruce file '!$1:$1, 0)), $A5), 0) -> 0 | L5: =SUM(B5:K5) -> 1
A6: Begusarai | B6: =IFERROR(SUMIFS(INDEX('Soruce file '!$A:$Z, 0, MATCH("Mobile Usage", 'Soruce file '!$1:$1, 0)), INDEX('Soruce file '!$A:$Z, 0, MATCH("Date", 'Soruce file '!$1:$1, 0)), $B$1, INDEX('Soruce file '!$A:$Z, 0, MATCH("GA*", 'Soruce file '!$1:$1, 0)), $A6), 0) -> 0 | C6: =IFERROR(SUMIFS(INDEX('Soruce file '!$A:$Z, 0, MATCH("No Seatbelt", 'Soruce file '!$1:$1, 0)), INDEX('Soruce file '!$A:$Z, 0, MATCH("Date", 'Soruce file '!$1:$1, 0)), $B$1, INDEX('Soruce file '!$A:$Z, 0, MATCH("GA*", 'Soruce file '!$1:$1, 0)), $A6), 0) -> 0 | D6: =IFERROR(SUMIFS(INDEX('Soruce file '!$A:$Z, 0, MATCH("Yawning", 'Soruce file '!$1:$1, 0)), INDEX('Soruce file '!$A:$Z, 0, MATCH("Date", 'Soruce file '!$1:$1, 0)), $B$1, INDEX('Soruce file '!$A:$Z, 0, MATCH("GA*", 'Soruce file '!$1:$1, 0)), $A6), 0) -> 0 | E6: =IFERROR(SUMIFS(INDEX('Soruce file '!$A:$Z, 0, MATCH("Fatigue", 'Soruce file '!$1:$1, 0)), INDEX('Soruce file '!$A:$Z, 0, MATCH("Date", 'Soruce file '!$1:$1, 0)), $B$1, INDEX('Soruce file '!$A:$Z, 0, MATCH("GA*", 'Soruce file '!$1:$1, 0)), $A6), 0) -> 0 | F6: =IFERROR(SUMIFS(INDEX('Soruce file '!$A:$Z, 0, MATCH("Harsh Braking", 'Soruce file '!$1:$1, 0)), INDEX('Soruce file '!$A:$Z, 0, MATCH("Date", 'Soruce file '!$1:$1, 0)), $B$1, INDEX('Soruce file '!$A:$Z, 0, MATCH("GA*", 'Soruce file '!$1:$1, 0)), $A6), 0) -> 0 | G6: =IFERROR(SUMIFS(INDEX('Soruce file '!$A:$Z, 0, MATCH("Overspeed", 'Soruce file '!$1:$1, 0)), INDEX('Soruce file '!$A:$Z, 0, MATCH("Date", 'Soruce file '!$1:$1, 0)), $B$1, INDEX('Soruce file '!$A:$Z, 0, MATCH("GA*", 'Soruce file '!$1:$1, 0)), $A6), 0) -> 0 | H6: =IFERROR(SUMIFS(INDEX('Soruce file '!$A:$Z, 0, MATCH("Sudden Acceleration", 'Soruce file '!$1:$1, 0)), INDEX('Soruce file '!$A:$Z, 0, MATCH("Date", 'Soruce file '!$1:$1, 0)), $B$1, INDEX('Soruce file '!$A:$Z, 0, MATCH("GA*", 'Soruce file '!$1:$1, 0)), $A6), 0) -> 0 | I6: =IFERROR(SUMIFS(INDEX('Soruce file '!$A:$Z, 0, MATCH("Camera Anomaly", 'Soruce file '!$1:$1, 0)), INDEX('Soruce file '!$A:$Z, 0, MATCH("Date", 'Soruce file '!$1:$1, 0)), $B$1, INDEX('Soruce file '!$A:$Z, 0, MATCH("GA*", 'Soruce file '!$1:$1, 0)), $A6), 0) -> 0 | J6: =IFERROR(SUMIFS(INDEX('Soruce file '!$A:$Z, 0, MATCH("CD", 'Soruce file '!$1:$1, 0)), INDEX('Soruce file '!$A:$Z, 0, MATCH("Date", 'Soruce file '!$1:$1, 0)), $B$1, INDEX('Soruce file '!$A:$Z, 0, MATCH("GA*", 'Soruce file '!$1:$1, 0)), $A6), 0) -> 0 | K6: =IFERROR(SUMIFS(INDEX('Soruce file '!$A:$Z, 0, MATCH("Night Driving", 'Soruce file '!$1:$1, 0)), INDEX('Soruce file '!$A:$Z, 0, MATCH("Date", 'Soruce file '!$1:$1, 0)), $B$1, INDEX('Soruce file '!$A:$Z, 0, MATCH("GA*", 'Soruce file '!$1:$1, 0)), $A6), 0) -> 0 | L6: =SUM(B6:K6) -> 0
A7: Bhopal | B7: =IFERROR(SUMIFS(INDEX('Soruce file '!$A:$Z, 0, MATCH("Mobile Usage", 'Soruce file '!$1:$1, 0)), INDEX('Soruce file '!$A:$Z, 0, MATCH("Date", 'Soruce file '!$1:$1, 0)), $B$1, INDEX('Soruce file '!$A:$Z, 0, MATCH("GA*", 'Soruce file '!$1:$1, 0)), $A7), 0) -> 1 | C7: =IFERROR(SUMIFS(INDEX('Soruce file '!$A:$Z, 0, MATCH("No Seatbelt", 'Soruce file '!$1:$1, 0)), INDEX('Soruce file '!$A:$Z, 0, MATCH("Date", 'Soruce file '!$1:$1, 0)), $B$1, INDEX('Soruce file '!$A:$Z, 0, MATCH("GA*", 'Soruce file '!$1:$1, 0)), $A7), 0) -> 0 | D7: =IFERROR(SUMIFS(INDEX('Soruce file '!$A:$Z, 0, MATCH("Yawning", 'Soruce file '!$1:$1, 0)), INDEX('Soruce file '!$A:$Z, 0, MATCH("Date", 'Soruce file '!$1:$1, 0)), $B$1, INDEX('Soruce file '!$A:$Z, 0, MATCH("GA*", 'Soruce file '!$1:$1, 0)), $A7), 0) -> 0 | E7: =IFERROR(SUMIFS(INDEX('Soruce file '!$A:$Z, 0, MATCH("Fatigue", 'Soruce file '!$1:$1, 0)), INDEX('Soruce file '!$A:$Z, 0, MATCH("Date", 'Soruce file '!$1:$1, 0)), $B$1, INDEX('Soruce file '!$A:$Z, 0, MATCH("GA*", 'Soruce file '!$1:$1, 0)), $A7), 0) -> 0 | F7: =IFERROR(SUMIFS(INDEX('Soruce file '!$A:$Z, 0, MATCH("Harsh Braking", 'Soruce file '!$1:$1, 0)), INDEX('Soruce file '!$A:$Z, 0, MATCH("Date", 'Soruce file '!$1:$1, 0)), $B$1, INDEX('Soruce file '!$A:$Z, 0, MATCH("GA*", 'Soruce file '!$1:$1, 0)), $A7), 0) -> 0 | G7: =IFERROR(SUMIFS(INDEX('Soruce file '!$A:$Z, 0, MATCH("Overspeed", 'Soruce file '!$1:$1, 0)), INDEX('Soruce file '!$A:$Z, 0, MATCH("Date", 'Soruce file '!$1:$1, 0)), $B$1, INDEX('Soruce file '!$A:$Z, 0, MATCH("GA*", 'Soruce file '!$1:$1, 0)), $A7), 0) -> 0 | H7: =IFERROR(SUMIFS(INDEX('Soruce file '!$A:$Z, 0, MATCH("Sudden Acceleration", 'Soruce file '!$1:$1, 0)), INDEX('Soruce file '!$A:$Z, 0, MATCH("Date", 'Soruce file '!$1:$1, 0)), $B$1, INDEX('Soruce file '!$A:$Z, 0, MATCH("GA*", 'Soruce file '!$1:$1, 0)), $A7), 0) -> 0 | I7: =IFERROR(SUMIFS(INDEX('Soruce file '!$A:$Z, 0, MATCH("Camera Anomaly", 'Soruce file '!$1:$1, 0)), INDEX('Soruce file '!$A:$Z, 0, MATCH("Date", 'Soruce file '!$1:$1, 0)), $B$1, INDEX('Soruce file '!$A:$Z, 0, MATCH("GA*", 'Soruce file '!$1:$1, 0)), $A7), 0) -> 0 | J7: =IFERROR(SUMIFS(INDEX('Soruce file '!$A:$Z, 0, MATCH("CD", 'Soruce file '!$1:$1, 0)), INDEX('Soruce file '!$A:$Z, 0, MATCH("Date", 'Soruce file '!$1:$1, 0)), $B$1, INDEX('Soruce file '!$A:$Z, 0, MATCH("GA*", 'Soruce file '!$1:$1, 0)), $A7), 0) -> 0 | K7: =IFERROR(SUMIFS(INDEX('Soruce file '!$A:$Z, 0, MATCH("Night Driving", 'Soruce file '!$1:$1, 0)), INDEX('Soruce file '!$A:$Z, 0, MATCH("Date", 'Soruce file '!$1:$1, 0)), $B$1, INDEX('Soruce file '!$A:$Z, 0, MATCH("GA*", 'Soruce file '!$1:$1, 0)), $A7), 0) -> 0 | L7: =SUM(B7:K7) -> 1
A8: BJJ | B8: =IFERROR(SUMIFS(INDEX('Soruce file '!$A:$Z, 0, MATCH("Mobile Usage", 'Soruce file '!$1:$1, 0)), INDEX('Soruce file '!$A:$Z, 0, MATCH("Date", 'Soruce file '!$1:$1, 0)), $B$1, INDEX('Soruce file '!$A:$Z, 0, MATCH("GA*", 'Soruce file '!$1:$1, 0)), $A8), 0) -> 0 | C8: =IFERROR(SUMIFS(INDEX('Soruce file '!$A:$Z, 0, MATCH("No Seatbelt", 'Soruce file '!$1:$1, 0)), INDEX('Soruce file '!$A:$Z, 0, MATCH("Date", 'Soruce file '!$1:$1, 0)), $B$1, INDEX('Soruce file '!$A:$Z, 0, MATCH("GA*", 'Soruce file '!$1:$1, 0)), $A8), 0) -> 0 | D8: =IFERROR(SUMIFS(INDEX('Soruce file '!$A:$Z, 0, MATCH("Yawning", 'Soruce file '!$1:$1, 0)), INDEX('Soruce file '!$A:$Z, 0, MATCH("Date", 'Soruce file '!$1:$1, 0)), $B$1, INDEX('Soruce file '!$A:$Z, 0, MATCH("GA*", 'Soruce file '!$1:$1, 0)), $A8), 0) -> 0 | E8: =IFERROR(SUMIFS(INDEX('Soruce file '!$A:$Z, 0, MATCH("Fatigue", 'Soruce file '!$1:$1, 0)), INDEX('Soruce file '!$A:$Z, 0, MATCH("Date", 'Soruce file '!$1:$1, 0)), $B$1, INDEX('Soruce file '!$A:$Z, 0, MATCH("GA*", 'Soruce file '!$1:$1, 0)), $A8), 0) -> 0 | F8: =IFERROR(SUMIFS(INDEX('Soruce file '!$A:$Z, 0, MATCH("Harsh Braking", 'Soruce file '!$1:$1, 0)), INDEX('Soruce file '!$A:$Z, 0, MATCH("Date", 'Soruce file '!$1:$1, 0)), $B$1, INDEX('Soruce file '!$A:$Z, 0, MATCH("GA*", 'Soruce file '!$1:$1, 0)), $A8), 0) -> 0 | G8: =IFERROR(SUMIFS(INDEX('Soruce file '!$A:$Z, 0, MATCH("Overspeed", 'Soruce file '!$1:$1, 0)), INDEX('Soruce file '!$A:$Z, 0, MATCH("Date", 'Soruce file '!$1:$1, 0)), $B$1, INDEX('Soruce file '!$A:$Z, 0, MATCH("GA*", 'Soruce file '!$1:$1, 0)), $A8), 0) -> 0 | H8: =IFERROR(SUMIFS(INDEX('Soruce file '!$A:$Z, 0, MATCH("Sudden Acceleration", 'Soruce file '!$1:$1, 0)), INDEX('Soruce file '!$A:$Z, 0, MATCH("Date", 'Soruce file '!$1:$1, 0)), $B$1, INDEX('Soruce file '!$A:$Z, 0, MATCH("GA*", 'Soruce file '!$1:$1, 0)), $A8), 0) -> 0 | I8: =IFERROR(SUMIFS(INDEX('Soruce file '!$A:$Z, 0, MATCH("Camera Anomaly", 'Soruce file '!$1:$1, 0)), INDEX('Soruce file '!$A:$Z, 0, MATCH("Date", 'Soruce file '!$1:$1, 0)), $B$1, INDEX('Soruce file '!$A:$Z, 0, MATCH("GA*", 'Soruce file '!$1:$1, 0)), $A8), 0) -> 1 | J8: =IFERROR(SUMIFS(INDEX('Soruce file '!$A:$Z, 0, MATCH("CD", 'Soruce file '!$1:$1, 0)), INDEX('Soruce file '!$A:$Z, 0, MATCH("Date", 'Soruce file '!$1:$1, 0)), $B$1, INDEX('Soruce file '!$A:$Z, 0, MATCH("GA*", 'Soruce file '!$1:$1, 0)), $A8), 0) -> 0 | K8: =IFERROR(SUMIFS(INDEX('Soruce file '!$A:$Z, 0, MATCH("Night Driving", 'Soruce file '!$1:$1, 0)), INDEX('Soruce file '!$A:$Z, 0, MATCH("Date", 'Soruce file '!$1:$1, 0)), $B$1, INDEX('Soruce file '!$A:$Z, 0, MATCH("GA*", 'Soruce file '!$1:$1, 0)), $A8), 0) -> 0 | L8: =SUM(B8:K8) -> 1
A9: BKR | B9: =IFERROR(SUMIFS(INDEX('Soruce file '!$A:$Z, 0, MATCH("Mobile Usage", 'Soruce file '!$1:$1, 0)), INDEX('Soruce file '!$A:$Z, 0, MATCH("Date", 'Soruce file '!$1:$1, 0)), $B$1, INDEX('Soruce file '!$A:$Z, 0, MATCH("GA*", 'Soruce file '!$1:$1, 0)), $A9), 0) -> 0 | C9: =IFERROR(SUMIFS(INDEX('Soruce file '!$A:$Z, 0, MATCH("No Seatbelt", 'Soruce file '!$1:$1, 0)), INDEX('Soruce file '!$A:$Z, 0, MATCH("Date", 'Soruce file '!$1:$1, 0)), $B$1, INDEX('Soruce file '!$A:$Z, 0, MATCH("GA*", 'Soruce file '!$1:$1, 0)), $A9), 0) -> 0 | D9: =IFERROR(SUMIFS(INDEX('Soruce file '!$A:$Z, 0, MATCH("Yawning", 'Soruce file '!$1:$1, 0)), INDEX('Soruce file '!$A:$Z, 0, MATCH("Date", 'Soruce file '!$1:$1, 0)), $B$1, INDEX('Soruce file '!$A:$Z, 0, MATCH("GA*", 'Soruce file '!$1:$1, 0)), $A9), 0) -> 0 | E9: =IFERROR(SUMIFS(INDEX('Soruce file '!$A:$Z, 0, MATCH("Fatigue", 'Soruce file '!$1:$1, 0)), INDEX('Soruce file '!$A:$Z, 0, MATCH("Date", 'Soruce file '!$1:$1, 0)), $B$1, INDEX('Soruce file '!$A:$Z, 0, MATCH("GA*", 'Soruce file '!$1:$1, 0)), $A9), 0) -> 0 | F9: =IFERROR(SUMIFS(INDEX('Soruce file '!$A:$Z, 0, MATCH("Harsh Braking", 'Soruce file '!$1:$1, 0)), INDEX('Soruce file '!$A:$Z, 0, MATCH("Date", 'Soruce file '!$1:$1, 0)), $B$1, INDEX('Soruce file '!$A:$Z, 0, MATCH("GA*", 'Soruce file '!$1:$1, 0)), $A9), 0) -> 0 | G9: =IFERROR(SUMIFS(INDEX('Soruce file '!$A:$Z, 0, MATCH("Overspeed", 'Soruce file '!$1:$1, 0)), INDEX('Soruce file '!$A:$Z, 0, MATCH("Date", 'Soruce file '!$1:$1, 0)), $B$1, INDEX('Soruce file '!$A:$Z, 0, MATCH("GA*", 'Soruce file '!$1:$1, 0)), $A9), 0) -> 0 | H9: =IFERROR(SUMIFS(INDEX('Soruce file '!$A:$Z, 0, MATCH("Sudden Acceleration", 'Soruce file '!$1:$1, 0)), INDEX('Soruce file '!$A:$Z, 0, MATCH("Date", 'Soruce file '!$1:$1, 0)), $B$1, INDEX('Soruce file '!$A:$Z, 0, MATCH("GA*", 'Soruce file '!$1:$1, 0)), $A9), 0) -> 0 | I9: =IFERROR(SUMIFS(INDEX('Soruce file '!$A:$Z, 0, MATCH("Camera Anomaly", 'Soruce file '!$1:$1, 0)), INDEX('Soruce file '!$A:$Z, 0, MATCH("Date", 'Soruce file '!$1:$1, 0)), $B$1, INDEX('Soruce file '!$A:$Z, 0, MATCH("GA*", 'Soruce file '!$1:$1, 0)), $A9), 0) -> 0 | J9: =IFERROR(SUMIFS(INDEX('Soruce file '!$A:$Z, 0, MATCH("CD", 'Soruce file '!$1:$1, 0)), INDEX('Soruce file '!$A:$Z, 0, MATCH("Date", 'Soruce file '!$1:$1, 0)), $B$1, INDEX('Soruce file '!$A:$Z, 0, MATCH("GA*", 'Soruce file '!$1:$1, 0)), $A9), 0) -> 0 | K9: =IFERROR(SUMIFS(INDEX('Soruce file '!$A:$Z, 0, MATCH("Night Driving", 'Soruce file '!$1:$1, 0)), INDEX('Soruce file '!$A:$Z, 0, MATCH("Date", 'Soruce file '!$1:$1, 0)), $B$1, INDEX('Soruce file '!$A:$Z, 0, MATCH("GA*", 'Soruce file '!$1:$1, 0)), $A9), 0) -> 0 | L9: =SUM(B9:K9) -> 0
A10: Chittoor | B10: =IFERROR(SUMIFS(INDEX('Soruce file '!$A:$Z, 0, MATCH("Mobile Usage", 'Soruce file '!$1:$1, 0)), INDEX('Soruce file '!$A:$Z, 0, MATCH("Date", 'Soruce file '!$1:$1, 0)), $B$1, INDEX('Soruce file '!$A:$Z, 0, MATCH("GA*", 'Soruce file '!$1:$1, 0)), $A10), 0) -> 0 | C10: =IFERROR(SUMIFS(INDEX('Soruce file '!$A:$Z, 0, MATCH("No Seatbelt", 'Soruce file '!$1:$1, 0)), INDEX('Soruce file '!$A:$Z, 0, MATCH("Date", 'Soruce file '!$1:$1, 0)), $B$1, INDEX('Soruce file '!$A:$Z, 0, MATCH("GA*", 'Soruce file '!$1:$1, 0)), $A10), 0) -> 0 | D10: =IFERROR(SUMIFS(INDEX('Soruce file '!$A:$Z, 0, MATCH("Yawning", 'Soruce file '!$1:$1, 0)), INDEX('Soruce file '!$A:$Z, 0, MATCH("Date", 'Soruce file '!$1:$1, 0)), $B$1, INDEX('Soruce file '!$A:$Z, 0, MATCH("GA*", 'Soruce file '!$1:$1, 0)), $A10), 0) -> 0 | E10: =IFERROR(SUMIFS(INDEX('Soruce file '!$A:$Z, 0, MATCH("Fatigue", 'Soruce file '!$1:$1, 0)), INDEX('Soruce file '!$A:$Z, 0, MATCH("Date", 'Soruce file '!$1:$1, 0)), $B$1, INDEX('Soruce file '!$A:$Z, 0, MATCH("GA*", 'Soruce file '!$1:$1, 0)), $A10), 0) -> 0 | F10: =IFERROR(SUMIFS(INDEX('Soruce file '!$A:$Z, 0, MATCH("Harsh Braking", 'Soruce file '!$1:$1, 0)), INDEX('Soruce file '!$A:$Z, 0, MATCH("Date", 'Soruce file '!$1:$1, 0)), $B$1, INDEX('Soruce file '!$A:$Z, 0, MATCH("GA*", 'Soruce file '!$1:$1, 0)), $A10), 0) -> 0 | G10: =IFERROR(SUMIFS(INDEX('Soruce file '!$A:$Z, 0, MATCH("Overspeed", 'Soruce file '!$1:$1, 0)), INDEX('Soruce file '!$A:$Z, 0, MATCH("Date", 'Soruce file '!$1:$1, 0)), $B$1, INDEX('Soruce file '!$A:$Z, 0, MATCH("GA*", 'Soruce file '!$1:$1, 0)), $A10), 0) -> 0 | H10: =IFERROR(SUMIFS(INDEX('Soruce file '!$A:$Z, 0, MATCH("Sudden Acceleration", 'Soruce file '!$1:$1, 0)), INDEX('Soruce file '!$A:$Z, 0, MATCH("Date", 'Soruce file '!$1:$1, 0)), $B$1, INDEX('Soruce file '!$A:$Z, 0, MATCH("GA*", 'Soruce file '!$1:$1, 0)), $A10), 0) -> 0 | I10: =IFERROR(SUMIFS(INDEX('Soruce file '!$A:$Z, 0, MATCH("Camera Anomaly", 'Soruce file '!$1:$1, 0)), INDEX('Soruce file '!$A:$Z, 0, MATCH("Date", 'Soruce file '!$1:$1, 0)), $B$1, INDEX('Soruce file '!$A:$Z, 0, MATCH("GA*", 'Soruce file '!$1:$1, 0)), $A10), 0) -> 0 | J10: =IFERROR(SUMIFS(INDEX('Soruce file '!$A:$Z, 0, MATCH("CD", 'Soruce file '!$1:$1, 0)), INDEX('Soruce file '!$A:$Z, 0, MATCH("Date", 'Soruce file '!$1:$1, 0)), $B$1, INDEX('Soruce file '!$A:$Z, 0, MATCH("GA*", 'Soruce file '!$1:$1, 0)), $A10), 0) -> 0 | K10: =IFERROR(SUMIFS(INDEX('Soruce file '!$A:$Z, 0, MATCH("Night Driving", 'Soruce file '!$1:$1, 0)), INDEX('Soruce file '!$A:$Z, 0, MATCH("Date", 'Soruce file '!$1:$1, 0)), $B$1, INDEX('Soruce file '!$A:$Z, 0, MATCH("GA*", 'Soruce file '!$1:$1, 0)), $A10), 0) -> 0 | L10: =SUM(B10:K10) -> 0
A11: CHK | B11: =IFERROR(SUMIFS(INDEX('Soruce file '!$A:$Z, 0, MATCH("Mobile Usage", 'Soruce file '!$1:$1, 0)), INDEX('Soruce file '!$A:$Z, 0, MATCH("Date", 'Soruce file '!$1:$1, 0)), $B$1, INDEX('Soruce file '!$A:$Z, 0, MATCH("GA*", 'Soruce file '!$1:$1, 0)), $A11), 0) -> 0 | C11: =IFERROR(SUMIFS(INDEX('Soruce file '!$A:$Z, 0, MATCH("No Seatbelt", 'Soruce file '!$1:$1, 0)), INDEX('Soruce file '!$A:$Z, 0, MATCH("Date", 'Soruce file '!$1:$1, 0)), $B$1, INDEX('Soruce file '!$A:$Z, 0, MATCH("GA*", 'Soruce file '!$1:$1, 0)), $A11), 0) -> 0 | D11: =IFERROR(SUMIFS(INDEX('Soruce file '!$A:$Z, 0, MATCH("Yawning", 'Soruce file '!$1:$1, 0)), INDEX('Soruce file '!$A:$Z, 0, MATCH("Date", 'Soruce file '!$1:$1, 0)), $B$1, INDEX('Soruce file '!$A:$Z, 0, MATCH("GA*", 'Soruce file '!$1:$1, 0)), $A11), 0) -> 0 | E11: =IFERROR(SUMIFS(INDEX('Soruce file '!$A:$Z, 0, MATCH("Fatigue", 'Soruce file '!$1:$1, 0)), INDEX('Soruce file '!$A:$Z, 0, MATCH("Date", 'Soruce file '!$1:$1, 0)), $B$1, INDEX('Soruce file '!$A:$Z, 0, MATCH("GA*", 'Soruce file '!$1:$1, 0)), $A11), 0) -> 0 | F11: =IFERROR(SUMIFS(INDEX('Soruce file '!$A:$Z, 0, MATCH("Harsh Braking", 'Soruce file '!$1:$1, 0)), INDEX('Soruce file '!$A:$Z, 0, MATCH("Date", 'Soruce file '!$1:$1, 0)), $B$1, INDEX('Soruce file '!$A:$Z, 0, MATCH("GA*", 'Soruce file '!$1:$1, 0)), $A11), 0) -> 0 | G11: =IFERROR(SUMIFS(INDEX('Soruce file '!$A:$Z, 0, MATCH("Overspeed", 'Soruce file '!$1:$1, 0)), INDEX('Soruce file '!$A:$Z, 0, MATCH("Date", 'Soruce file '!$1:$1, 0)), $B$1, INDEX('Soruce file '!$A:$Z, 0, MATCH("GA*", 'Soruce file '!$1:$1, 0)), $A11), 0) -> 0 | H11: =IFERROR(SUMIFS(INDEX('Soruce file '!$A:$Z, 0, MATCH("Sudden Acceleration", 'Soruce file '!$1:$1, 0)), INDEX('Soruce file '!$A:$Z, 0, MATCH("Date", 'Soruce file '!$1:$1, 0)), $B$1, INDEX('Soruce file '!$A:$Z, 0, MATCH("GA*", 'Soruce file '!$1:$1, 0)), $A11), 0) -> 0 | I11: =IFERROR(SUMIFS(INDEX('Soruce file '!$A:$Z, 0, MATCH("Camera Anomaly", 'Soruce file '!$1:$1, 0)), INDEX('Soruce file '!$A:$Z, 0, MATCH("Date", 'Soruce file '!$1:$1, 0)), $B$1, INDEX('Soruce file '!$A:$Z, 0, MATCH("GA*", 'Soruce file '!$1:$1, 0)), $A11), 0) -> 0 | J11: =IFERROR(SUMIFS(INDEX('Soruce file '!$A:$Z, 0, MATCH("CD", 'Soruce file '!$1:$1, 0)), INDEX('Soruce file '!$A:$Z, 0, MATCH("Date", 'Soruce file '!$1:$1, 0)), $B$1, INDEX('Soruce file '!$A:$Z, 0, MATCH("GA*", 'Soruce file '!$1:$1, 0)), $A11), 0) -> 0 | K11: =IFERROR(SUMIFS(INDEX('Soruce file '!$A:$Z, 0, MATCH("Night Driving", 'Soruce file '!$1:$1, 0)), INDEX('Soruce file '!$A:$Z, 0, MATCH("Date", 'Soruce file '!$1:$1, 0)), $B$1, INDEX('Soruce file '!$A:$Z, 0, MATCH("GA*", 'Soruce file '!$1:$1, 0)), $A11), 0) -> 0 | L11: =SUM(B11:K11) -> 0
A12: Dahej | B12: =IFERROR(SUMIFS(INDEX('Soruce file '!$A:$Z, 0, MATCH("Mobile Usage", 'Soruce file '!$1:$1, 0)), INDEX('Soruce file '!$A:$Z, 0, MATCH("Date", 'Soruce file '!$1:$1, 0)), $B$1, INDEX('Soruce file '!$A:$Z, 0, MATCH("GA*", 'Soruce file '!$1:$1, 0)), $A12), 0) -> 1 | C12: =IFERROR(SUMIFS(INDEX('Soruce file '!$A:$Z, 0, MATCH("No Seatbelt", 'Soruce file '!$1:$1, 0)), INDEX('Soruce file '!$A:$Z, 0, MATCH("Date", 'Soruce file '!$1:$1, 0)), $B$1, INDEX('Soruce file '!$A:$Z, 0, MATCH("GA*", 'Soruce file '!$1:$1, 0)), $A12), 0) -> 0 | D12: =IFERROR(SUMIFS(INDEX('Soruce file '!$A:$Z, 0, MATCH("Yawning", 'Soruce file '!$1:$1, 0)), INDEX('Soruce file '!$A:$Z, 0, MATCH("Date", 'Soruce file '!$1:$1, 0)), $B$1, INDEX('Soruce file '!$A:$Z, 0, MATCH("GA*", 'Soruce file '!$1:$1, 0)), $A12), 0) -> 0 | E12: =IFERROR(SUMIFS(INDEX('Soruce file '!$A:$Z, 0, MATCH("Fatigue", 'Soruce file '!$1:$1, 0)), INDEX('Soruce file '!$A:$Z, 0, MATCH("Date", 'Soruce file '!$1:$1, 0)), $B$1, INDEX('Soruce file '!$A:$Z, 0, MATCH("GA*", 'Soruce file '!$1:$1, 0)), $A12), 0) -> 0 | F12: =IFERROR(SUMIFS(INDEX('Soruce file '!$A:$Z, 0, MATCH("Harsh Braking", 'Soruce file '!$1:$1, 0)), INDEX('Soruce file '!$A:$Z, 0, MATCH("Date", 'Soruce file '!$1:$1, 0)), $B$1, INDEX('Soruce file '!$A:$Z, 0, MATCH("GA*", 'Soruce file '!$1:$1, 0)), $A12), 0) -> 0 | G12: =IFERROR(SUMIFS(INDEX('Soruce file '!$A:$Z, 0, MATCH("Overspeed", 'Soruce file '!$1:$1, 0)), INDEX('Soruce file '!$A:$Z, 0, MATCH("Date", 'Soruce file '!$1:$1, 0)), $B$1, INDEX('Soruce file '!$A:$Z, 0, MATCH("GA*", 'Soruce file '!$1:$1, 0)), $A12), 0) -> 0 | H12: =IFERROR(SUMIFS(INDEX('Soruce file '!$A:$Z, 0, MATCH("Sudden Acceleration", 'Soruce file '!$1:$1, 0)), INDEX('Soruce file '!$A:$Z, 0, MATCH("Date", 'Soruce file '!$1:$1, 0)), $B$1, INDEX('Soruce file '!$A:$Z, 0, MATCH("GA*", 'Soruce file '!$1:$1, 0)), $A12), 0) -> 0 | I12: =IFERROR(SUMIFS(INDEX('Soruce file '!$A:$Z, 0, MATCH("Camera Anomaly", 'Soruce file '!$1:$1, 0)), INDEX('Soruce file '!$A:$Z, 0, MATCH("Date", 'Soruce file '!$1:$1, 0)), $B$1, INDEX('Soruce file '!$A:$Z, 0, MATCH("GA*", 'Soruce file '!$1:$1, 0)), $A12), 0) -> 0 | J12: =IFERROR(SUMIFS(INDEX('Soruce file '!$A:$Z, 0, MATCH("CD", 'Soruce file '!$1:$1, 0)), INDEX('Soruce file '!$A:$Z, 0, MATCH("Date", 'Soruce file '!$1:$1, 0)), $B$1, INDEX('Soruce file '!$A:$Z, 0, MATCH("GA*", 'Soruce file '!$1:$1, 0)), $A12), 0) -> 0 | K12: =IFERROR(SUMIFS(INDEX('Soruce file '!$A:$Z, 0, MATCH("Night Driving", 'Soruce file '!$1:$1, 0)), INDEX('Soruce file '!$A:$Z, 0, MATCH("Date", 'Soruce file '!$1:$1, 0)), $B$1, INDEX('Soruce file '!$A:$Z, 0, MATCH("GA*", 'Soruce file '!$1:$1, 0)), $A12), 0) -> 0 | L12: =SUM(B12:K12) -> 1
A13: Ennore | B13: =IFERROR(SUMIFS(INDEX('Soruce file '!$A:$Z, 0, MATCH("Mobile Usage", 'Soruce file '!$1:$1, 0)), INDEX('Soruce file '!$A:$Z, 0, MATCH("Date", 'Soruce file '!$1:$1, 0)), $B$1, INDEX('Soruce file '!$A:$Z, 0, MATCH("GA*", 'Soruce file '!$1:$1, 0)), $A13), 0) -> 0 | C13: =IFERROR(SUMIFS(INDEX('Soruce file '!$A:$Z, 0, MATCH("No Seatbelt", 'Soruce file '!$1:$1, 0)), INDEX('Soruce file '!$A:$Z, 0, MATCH("Date", 'Soruce file '!$1:$1, 0)), $B$1, INDEX('Soruce file '!$A:$Z, 0, MATCH("GA*", 'Soruce file '!$1:$1, 0)), $A13), 0) -> 0 | D13: =IFERROR(SUMIFS(INDEX('Soruce file '!$A:$Z, 0, MATCH("Yawning", 'Soruce file '!$1:$1, 0)), INDEX('Soruce file '!$A:$Z, 0, MATCH("Date", 'Soruce file '!$1:$1, 0)), $B$1, INDEX('Soruce file '!$A:$Z, 0, MATCH("GA*", 'Soruce file '!$1:$1, 0)), $A13), 0) -> 0 | E13: =IFERROR(SUMIFS(INDEX('Soruce file '!$A:$Z, 0, MATCH("Fatigue", 'Soruce file '!$1:$1, 0)), INDEX('Soruce file '!$A:$Z, 0, MATCH("Date", 'Soruce file '!$1:$1, 0)), $B$1, INDEX('Soruce file '!$A:$Z, 0, MATCH("GA*", 'Soruce file '!$1:$1, 0)), $A13), 0) -> 1 | F13: =IFERROR(SUMIFS(INDEX('Soruce file '!$A:$Z, 0, MATCH("Harsh Braking", 'Soruce file '!$1:$1, 0)), INDEX('Soruce file '!$A:$Z, 0, MATCH("Date", 'Soruce file '!$1:$1, 0)), $B$1, INDEX('Soruce file '!$A:$Z, 0, MATCH("GA*", 'Soruce file '!$1:$1, 0)), $A13), 0) -> 0 | G13: =IFERROR(SUMIFS(INDEX('Soruce file '!$A:$Z, 0, MATCH("Overspeed", 'Soruce file '!$1:$1, 0)), INDEX('Soruce file '!$A:$Z, 0, MATCH("Date", 'Soruce file '!$1:$1, 0)), $B$1, INDEX('Soruce file '!$A:$Z, 0, MATCH("GA*", 'Soruce file '!$1:$1, 0)), $A13), 0) -> 0 | H13: =IFERROR(SUMIFS(INDEX('Soruce file '!$A:$Z, 0, MATCH("Sudden Acceleration", 'Soruce file '!$1:$1, 0)), INDEX('Soruce file '!$A:$Z, 0, MATCH("Date", 'Soruce file '!$1:$1, 0)), $B$1, INDEX('Soruce file '!$A:$Z, 0, MATCH("GA*", 'Soruce file '!$1:$1, 0)), $A13), 0) -> 0 | I13: =IFERROR(SUMIFS(INDEX('Soruce file '!$A:$Z, 0, MATCH("Camera Anomaly", 'Soruce file '!$1:$1, 0)), INDEX('Soruce file '!$A:$Z, 0, MATCH("Date", 'Soruce file '!$1:$1, 0)), $B$1, INDEX('Soruce file '!$A:$Z, 0, MATCH("GA*", 'Soruce file '!$1:$1, 0)), $A13), 0) -> 1 | J13: =IFERROR(SUMIFS(INDEX('Soruce file '!$A:$Z, 0, MATCH("CD", 'Soruce file '!$1:$1, 0)), INDEX('Soruce file '!$A:$Z, 0, MATCH("Date", 'Soruce file '!$1:$1, 0)), $B$1, INDEX('Soruce file '!$A:$Z, 0, MATCH("GA*", 'Soruce file '!$1:$1, 0)), $A13), 0) -> 0 | K13: =IFERROR(SUMIFS(INDEX('Soruce file '!$A:$Z, 0, MATCH("Night Driving", 'Soruce file '!$1:$1, 0)), INDEX('Soruce file '!$A:$Z, 0, MATCH("Date", 'Soruce file '!$1:$1, 0)), $B$1, INDEX('Soruce file '!$A:$Z, 0, MATCH("GA*", 'Soruce file '!$1:$1, 0)), $A13), 0) -> 0 | L13: =SUM(B13:K13) -> 2
A14: Hazira | B14: =IFERROR(SUMIFS(INDEX('Soruce file '!$A:$Z, 0, MATCH("Mobile Usage", 'Soruce file '!$1:$1, 0)), INDEX('Soruce file '!$A:$Z, 0, MATCH("Date", 'Soruce file '!$1:$1, 0)), $B$1, INDEX('Soruce file '!$A:$Z, 0, MATCH("GA*", 'Soruce file '!$1:$1, 0)), $A14), 0) -> 0 | C14: =IFERROR(SUMIFS(INDEX('Soruce file '!$A:$Z, 0, MATCH("No Seatbelt", 'Soruce file '!$1:$1, 0)), INDEX('Soruce file '!$A:$Z, 0, MATCH("Date", 'Soruce file '!$1:$1, 0)), $B$1, INDEX('Soruce file '!$A:$Z, 0, MATCH("GA*", 'Soruce file '!$1:$1, 0)), $A14), 0) -> 0 | D14: =IFERROR(SUMIFS(INDEX('Soruce file '!$A:$Z, 0, MATCH("Yawning", 'Soruce file '!$1:$1, 0)), INDEX('Soruce file '!$A:$Z, 0, MATCH("Date", 'Soruce file '!$1:$1, 0)), $B$1, INDEX('Soruce file '!$A:$Z, 0, MATCH("GA*", 'Soruce file '!$1:$1, 0)), $A14), 0) -> 0 | E14: =IFERROR(SUMIFS(INDEX('Soruce file '!$A:$Z, 0, MATCH("Fatigue", 'Soruce file '!$1:$1, 0)), INDEX('Soruce file '!$A:$Z, 0, MATCH("Date", 'Soruce file '!$1:$1, 0)), $B$1, INDEX('Soruce file '!$A:$Z, 0, MATCH("GA*", 'Soruce file '!$1:$1, 0)), $A14), 0) -> 0 | F14: =IFERROR(SUMIFS(INDEX('Soruce file '!$A:$Z, 0, MATCH("Harsh Braking", 'Soruce file '!$1:$1, 0)), INDEX('Soruce file '!$A:$Z, 0, MATCH("Date", 'Soruce file '!$1:$1, 0)), $B$1, INDEX('Soruce file '!$A:$Z, 0, MATCH("GA*", 'Soruce file '!$1:$1, 0)), $A14), 0) -> 0 | G14: =IFERROR(SUMIFS(INDEX('Soruce file '!$A:$Z, 0, MATCH("Overspeed", 'Soruce file '!$1:$1, 0)), INDEX('Soruce file '!$A:$Z, 0, MATCH("Date", 'Soruce file '!$1:$1, 0)), $B$1, INDEX('Soruce file '!$A:$Z, 0, MATCH("GA*", 'Soruce file '!$1:$1, 0)), $A14), 0) -> 0 | H14: =IFERROR(SUMIFS(INDEX('Soruce file '!$A:$Z, 0, MATCH("Sudden Acceleration", 'Soruce file '!$1:$1, 0)), INDEX('Soruce file '!$A:$Z, 0, MATCH("Date", 'Soruce file '!$1:$1, 0)), $B$1, INDEX('Soruce file '!$A:$Z, 0, MATCH("GA*", 'Soruce file '!$1:$1, 0)), $A14), 0) -> 0 | I14: =IFERROR(SUMIFS(INDEX('Soruce file '!$A:$Z, 0, MATCH("Camera Anomaly", 'Soruce file '!$1:$1, 0)), INDEX('Soruce file '!$A:$Z, 0, MATCH("Date", 'Soruce file '!$1:$1, 0)), $B$1, INDEX('Soruce file '!$A:$Z, 0, MATCH("GA*", 'Soruce file '!$1:$1, 0)), $A14), 0) -> 0 | J14: =IFERROR(SUMIFS(INDEX('Soruce file '!$A:$Z, 0, MATCH("CD", 'Soruce file '!$1:$1, 0)), INDEX('Soruce file '!$A:$Z, 0, MATCH("Date", 'Soruce file '!$1:$1, 0)), $B$1, INDEX('Soruce file '!$A:$Z, 0, MATCH("GA*", 'Soruce file '!$1:$1, 0)), $A14), 0) -> 0 | K14: =IFERROR(SUMIFS(INDEX('Soruce file '!$A:$Z, 0, MATCH("Night Driving", 'Soruce file '!$1:$1, 0)), INDEX('Soruce file '!$A:$Z, 0, MATCH("Date", 'Soruce file '!$1:$1, 0)), $B$1, INDEX('Soruce file '!$A:$Z, 0, MATCH("GA*", 'Soruce file '!$1:$1, 0)), $A14), 0) -> 0 | L14: =SUM(B14:K14) -> 0
... A24: Vellore | B24: =IFERROR(SUMIFS(INDEX('Soruce file '!$A:$Z, 0, MATCH("Mobile Usage", 'Soruce file '!$1:$1, 0)), INDEX('Soruce file '!$A:$Z, 0, MATCH("Date", 'Soruce file '!$1:$1, 0)), $B$1, INDEX('Soruce file '!$A:$Z, 0, MATCH("GA*", 'Soruce file '!$1:$1, 0)), $A24), 0) -> 0 | C24: =IFERROR(SUMIFS(INDEX('Soruce file '!$A:$Z, 0, MATCH("No Seatbelt", 'Soruce file '!$1:$1, 0)), INDEX('Soruce file '!$A:$Z, 0, MATCH("Date", 'Soruce file '!$1:$1, 0)), $B$1, INDEX('Soruce file '!$A:$Z, 0, MATCH("GA*", 'Soruce file '!$1:$1, 0)), $A24), 0) -> 0 | D24: =IFERROR(SUMIFS(INDEX('Soruce file '!$A:$Z, 0, MATCH("Yawning", 'Soruce file '!$1:$1, 0)), INDEX('Soruce file '!$A:$Z, 0, MATCH("Date", 'Soruce file '!$1:$1, 0)), $B$1, INDEX('Soruce file '!$A:$Z, 0, MATCH("GA*", 'Soruce file '!$1:$1, 0)), $A24), 0) -> 0 | E24: =IFERROR(SUMIFS(INDEX('Soruce file '!$A:$Z, 0, MATCH("Fatigue", 'Soruce file '!$1:$1, 0)), INDEX('Soruce file '!$A:$Z, 0, MATCH("Date", 'Soruce file '!$1:$1, 0)), $B$1, INDEX('Soruce file '!$A:$Z, 0, MATCH("GA*", 'Soruce file '!$1:$1, 0)), $A24), 0) -> 0 | F24: =IFERROR(SUMIFS(INDEX('Soruce file '!$A:$Z, 0, MATCH("Harsh Braking", 'Soruce file '!$1:$1, 0)), INDEX('Soruce file '!$A:$Z, 0, MATCH("Date", 'Soruce file '!$1:$1, 0)), $B$1, INDEX('Soruce file '!$A:$Z, 0, MATCH("GA*", 'Soruce file '!$1:$1, 0)), $A24), 0) -> 0 | G24: =IFERROR(SUMIFS(INDEX('Soruce file '!$A:$Z, 0, MATCH("Overspeed", 'Soruce file '!$1:$1, 0)), INDEX('Soruce file '!$A:$Z, 0, MATCH("Date", 'Soruce file '!$1:$1, 0)), $B$1, INDEX('Soruce file '!$A:$Z, 0, MATCH("GA*", 'Soruce file '!$1:$1, 0)), $A24), 0) -> 0 | H24: =IFERROR(SUMIFS(INDEX('Soruce file '!$A:$Z, 0, MATCH("Sudden Acceleration", 'Soruce file '!$1:$1, 0)), INDEX('Soruce file '!$A:$Z, 0, MATCH("Date", 'Soruce file '!$1:$1, 0)), $B$1, INDEX('Soruce file '!$A:$Z, 0, MATCH("GA*", 'Soruce file '!$1:$1, 0)), $A24), 0) -> 0 | I24: =IFERROR(SUMIFS(INDEX('Soruce file '!$A:$Z, 0, MATCH("Camera Anomaly", 'Soruce file '!$1:$1, 0)), INDEX('Soruce file '!$A:$Z, 0, MATCH("Date", 'Soruce file '!$1:$1, 0)), $B$1, INDEX('Soruce file '!$A:$Z, 0, MATCH("GA*", 'Soruce file '!$1:$1, 0)), $A24), 0) -> 0 | J24: =IFERROR(SUMIFS(INDEX('Soruce file '!$A:$Z, 0, MATCH("CD", 'Soruce file '!$1:$1, 0)), INDEX('Soruce file '!$A:$Z, 0, MATCH("Date", 'Soruce file '!$1:$1, 0)), $B$1, INDEX('Soruce file '!$A:$Z, 0, MATCH("GA*", 'Soruce file '!$1:$1, 0)), $A24), 0) -> 0 | K24: =IFERROR(SUMIFS(INDEX('Soruce file '!$A:$Z, 0, MATCH("Night Driving", 'Soruce file '!$1:$1, 0)), INDEX('Soruce file '!$A:$Z, 0, MATCH("Date", 'Soruce file '!$1:$1, 0)), $B$1, INDEX('Soruce file '!$A:$Z, 0, MATCH("GA*", 'Soruce file '!$1:$1, 0)), $A24), 0) -> 0 | L24: =SUM(B24:K24) -> 0
A25: Total | B25: =SUM(B3:B24) -> 6 | C25: =SUM(C3:C24) -> 2 | D25: =SUM(D3:D24) -> 0 | E25: =SUM(E3:E24) -> 1 | F25: =SUM(F3:F24) -> 0 | G25: =SUM(G3:G24) -> 1 | H25: =SUM(H3:H24) -> 0 | I25: =SUM(I3:I24) -> 2 | ... K25: =SUM(K3:K24) -> 0 | L25: =SUM(B25:K25) -> 12

Sheet Mar Mon Summ
A1: Report From Date | B1: =EOMONTH(MAX('Soruce file '!B:B), -1) + 1 -> 46082
A2: Location | B2: Mobile Usage | C2: No Seatbelt | D2: Yawning | E2: Driver Fatigue | F2: Harsh Braking | G2: Over speed | H2: Sudden Acceleration | I2: Camera Anomaly | J2: Continuous Driving | K2: Night Driving | L2: Total
A3: AKT | B3: =IFERROR(SUMIFS(INDEX('Soruce file '!$A:$Z, 0, MATCH("Mobile Usage", 'Soruce file '!$1:$1, 0)), INDEX('Soruce file '!$A:$Z, 0, MATCH("Date", 'Soruce file '!$1:$1, 0)), ">="&$B$1, INDEX('Soruce file '!$A:$Z, 0, MATCH("Date", 'Soruce file '!$1:$1, 0)), "<="&EOMONTH($B$1,0), INDEX('Soruce file '!$A:$Z, 0, MATCH("GA*", 'Soruce file '!$1:$1, 0)), $A3), 0) -> 17 | C3: =IFERROR(SUMIFS(INDEX('Soruce file '!$A:$Z, 0, MATCH("No Seatbelt", 'Soruce file '!$1:$1, 0)), INDEX('Soruce file '!$A:$Z, 0, MATCH("Date", 'Soruce file '!$1:$1, 0)), ">="&$B$1, INDEX('Soruce file '!$A:$Z, 0, MATCH("Date", 'Soruce file '!$1:$1, 0)), "<="&EOMONTH($B$1,0), INDEX('Soruce file '!$A:$Z, 0, MATCH("GA*", 'Soruce file '!$1:$1, 0)), $A3), 0) -> 1 | D3: =IFERROR(SUMIFS(INDEX('Soruce file '!$A:$Z, 0, MATCH("Yawning", 'Soruce file '!$1:$1, 0)), INDEX('Soruce file '!$A:$Z, 0, MATCH("Date", 'Soruce file '!$1:$1, 0)), ">="&$B$1, INDEX('Soruce file '!$A:$Z, 0, MATCH("Date", 'Soruce file '!$1:$1, 0)), "<="&EOMONTH($B$1,0), INDEX('Soruce file '!$A:$Z, 0, MATCH("GA*", 'Soruce file '!$1:$1, 0)), $A3), 0) -> 1 | E3: =IFERROR(SUMIFS(INDEX('Soruce file '!$A:$Z, 0, MATCH("Fatigue", 'Soruce file '!$1:$1, 0)), INDEX('Soruce file '!$A:$Z, 0, MATCH("Date", 'Soruce file '!$1:$1, 0)), ">="&$B$1, INDEX('Soruce file '!$A:$Z, 0, MATCH("Date", 'Soruce file '!$1:$1, 0)), "<="&EOMONTH($B$1,0), INDEX('Soruce file '!$A:$Z, 0, MATCH("GA*", 'Soruce file '!$1:$1, 0)), $A3), 0) -> 1 | F3: =IFERROR(SUMIFS(INDEX('Soruce file '!$A:$Z, 0, MATCH("Harsh Braking", 'Soruce file '!$1:$1, 0)), INDEX('Soruce file '!$A:$Z, 0, MATCH("Date", 'Soruce file '!$1:$1, 0)), ">="&$B$1, INDEX('Soruce file '!$A:$Z, 0, MATCH("Date", 'Soruce file '!$1:$1, 0)), "<="&EOMONTH($B$1,0), INDEX('Soruce file '!$A:$Z, 0, MATCH("GA*", 'Soruce file '!$1:$1, 0)), $A3), 0) -> 0 | G3: =IFERROR(SUMIFS(INDEX('Soruce file '!$A:$Z, 0, MATCH("Overspeed", 'Soruce file '!$1:$1, 0)), INDEX('Soruce file '!$A:$Z, 0, MATCH("Date", 'Soruce file '!$1:$1, 0)), ">="&$B$1, INDEX('Soruce file '!$A:$Z, 0, MATCH("Date", 'Soruce file '!$1:$1, 0)), "<="&EOMONTH($B$1,0), INDEX('Soruce file '!$A:$Z, 0, MATCH("GA*", 'Soruce file '!$1:$1, 0)), $A3), 0) -> 6 | H3: =IFERROR(SUMIFS(INDEX('Soruce file '!$A:$Z, 0, MATCH("Sudden Acceleration", 'Soruce file '!$1:$1, 0)), INDEX('Soruce file '!$A:$Z, 0, MATCH("Date", 'Soruce file '!$1:$1, 0)), ">="&$B$1, INDEX('Soruce file '!$A:$Z, 0, MATCH("Date", 'Soruce file '!$1:$1, 0)), "<="&EOMONTH($B$1,0), INDEX('Soruce file '!$A:$Z, 0, MATCH("GA*", 'Soruce file '!$1:$1, 0)), $A3), 0) -> 0 | I3: =IFERROR(SUMIFS(INDEX('Soruce file '!$A:$Z, 0, MATCH("Camera Anomaly", 'Soruce file '!$1:$1, 0)), INDEX('Soruce file '!$A:$Z, 0, MATCH("Date", 'Soruce file '!$1:$1, 0)), ">="&$B$1, INDEX('Soruce file '!$A:$Z, 0, MATCH("Date", 'Soruce file '!$1:$1, 0)), "<="&EOMONTH($B$1,0), INDEX('Soruce file '!$A:$Z, 0, MATCH("GA*", 'Soruce file '!$1:$1, 0)), $A3), 0) -> 2 | J3: =IFERROR(SUMIFS(INDEX('Soruce file '!$A:$Z, 0, MATCH("CD", 'Soruce file '!$1:$1, 0)), INDEX('Soruce file '!$A:$Z, 0, MATCH("Date", 'Soruce file '!$1:$1, 0)), ">="&$B$1, INDEX('Soruce file '!$A:$Z, 0, MATCH("Date", 'Soruce file '!$1:$1, 0)), "<="&EOMONTH($B$1,0), INDEX('Soruce file '!$A:$Z, 0, MATCH("GA*", 'Soruce file '!$1:$1, 0)), $A3), 0) -> 0 | K3: =IFERROR(SUMIFS(INDEX('Soruce file '!$A:$Z, 0, MATCH("Night Driving", 'Soruce file '!$1:$1, 0)), INDEX('Soruce file '!$A:$Z, 0, MATCH("Date", 'Soruce file '!$1:$1, 0)), ">="&$B$1, INDEX('Soruce file '!$A:$Z, 0, MATCH("Date", 'Soruce file '!$1:$1, 0)), "<="&EOMONTH($B$1,0), INDEX('Soruce file '!$A:$Z, 0, MATCH("GA*", 'Soruce file '!$1:$1, 0)), $A3), 0) -> 0 | L3: =SUM(B3:K3) -> 28
A4: ANK | B4: =IFERROR(SUMIFS(INDEX('Soruce file '!$A:$Z, 0, MATCH("Mobile Usage", 'Soruce file '!$1:$1, 0)), INDEX('Soruce file '!$A:$Z, 0, MATCH("Date", 'Soruce file '!$1:$1, 0)), ">="&$B$1, INDEX('Soruce file '!$A:$Z, 0, MATCH("Date", 'Soruce file '!$1:$1, 0)), "<="&EOMONTH($B$1,0), INDEX('Soruce file '!$A:$Z, 0, MATCH("GA*", 'Soruce file '!$1:$1, 0)), $A4), 0) -> 1 | C4: =IFERROR(SUMIFS(INDEX('Soruce file '!$A:$Z, 0, MATCH("No Seatbelt", 'Soruce file '!$1:$1, 0)), INDEX('Soruce file '!$A:$Z, 0, MATCH("Date", 'Soruce file '!$1:$1, 0)), ">="&$B$1, INDEX('Soruce file '!$A:$Z, 0, MATCH("Date", 'Soruce file '!$1:$1, 0)), "<="&EOMONTH($B$1,0), INDEX('Soruce file '!$A:$Z, 0, MATCH("GA*", 'Soruce file '!$1:$1, 0)), $A4), 0) -> 0 | D4: =IFERROR(SUMIFS(INDEX('Soruce file '!$A:$Z, 0, MATCH("Yawning", 'Soruce file '!$1:$1, 0)), INDEX('Soruce file '!$A:$Z, 0, MATCH("Date", 'Soruce file '!$1:$1, 0)), ">="&$B$1, INDEX('Soruce file '!$A:$Z, 0, MATCH("Date", 'Soruce file '!$1:$1, 0)), "<="&EOMONTH($B$1,0), INDEX('Soruce file '!$A:$Z, 0, MATCH("GA*", 'Soruce file '!$1:$1, 0)), $A4), 0) -> 1 | E4: =IFERROR(SUMIFS(INDEX('Soruce file '!$A:$Z, 0, MATCH("Fatigue", 'Soruce file '!$1:$1, 0)), INDEX('Soruce file '!$A:$Z, 0, MATCH("Date", 'Soruce file '!$1:$1, 0)), ">="&$B$1, INDEX('Soruce file '!$A:$Z, 0, MATCH("Date", 'Soruce file '!$1:$1, 0)), "<="&EOMONTH($B$1,0), INDEX('Soruce file '!$A:$Z, 0, MATCH("GA*", 'Soruce file '!$1:$1, 0)), $A4), 0) -> 2 | F4: =IFERROR(SUMIFS(INDEX('Soruce file '!$A:$Z, 0, MATCH("Harsh Braking", 'Soruce file '!$1:$1, 0)), INDEX('Soruce file '!$A:$Z, 0, MATCH("Date", 'Soruce file '!$1:$1, 0)), ">="&$B$1, INDEX('Soruce file '!$A:$Z, 0, MATCH("Date", 'Soruce file '!$1:$1, 0)), "<="&EOMONTH($B$1,0), INDEX('Soruce file '!$A:$Z, 0, MATCH("GA*", 'Soruce file '!$1:$1, 0)), $A4), 0) -> 0 | G4: =IFERROR(SUMIFS(INDEX('Soruce file '!$A:$Z, 0, MATCH("Overspeed", 'Soruce file '!$1:$1, 0)), INDEX('Soruce file '!$A:$Z, 0, MATCH("Date", 'Soruce file '!$1:$1, 0)), ">="&$B$1, INDEX('Soruce file '!$A:$Z, 0, MATCH("Date", 'Soruce file '!$1:$1, 0)), "<="&EOMONTH($B$1,0), INDEX('Soruce file '!$A:$Z, 0, MATCH("GA*", 'Soruce file '!$1:$1, 0)), $A4), 0) -> 0 | H4: =IFERROR(SUMIFS(INDEX('Soruce file '!$A:$Z, 0, MATCH("Sudden Acceleration", 'Soruce file '!$1:$1, 0)), INDEX('Soruce file '!$A:$Z, 0, MATCH("Date", 'Soruce file '!$1:$1, 0)), ">="&$B$1, INDEX('Soruce file '!$A:$Z, 0, MATCH("Date", 'Soruce file '!$1:$1, 0)), "<="&EOMONTH($B$1,0), INDEX('Soruce file '!$A:$Z, 0, MATCH("GA*", 'Soruce file '!$1:$1, 0)), $A4), 0) -> 0 | I4: =IFERROR(SUMIFS(INDEX('Soruce file '!$A:$Z, 0, MATCH("Camera Anomaly", 'Soruce file '!$1:$1, 0)), INDEX('Soruce file '!$A:$Z, 0, MATCH("Date", 'Soruce file '!$1:$1, 0)), ">="&$B$1, INDEX('Soruce file '!$A:$Z, 0, MATCH("Date", 'Soruce file '!$1:$1, 0)), "<="&EOMONTH($B$1,0), INDEX('Soruce file '!$A:$Z, 0, MATCH("GA*", 'Soruce file '!$1:$1, 0)), $A4), 0) -> 1 | J4: =IFERROR(SUMIFS(INDEX('Soruce file '!$A:$Z, 0, MATCH("CD", 'Soruce file '!$1:$1, 0)), INDEX('Soruce file '!$A:$Z, 0, MATCH("Date", 'Soruce file '!$1:$1, 0)), ">="&$B$1, INDEX('Soruce file '!$A:$Z, 0, MATCH("Date", 'Soruce file '!$1:$1, 0)), "<="&EOMONTH($B$1,0), INDEX('Soruce file '!$A:$Z, 0, MATCH("GA*", 'Soruce file '!$1:$1, 0)), $A4), 0) -> 0 | K4: =IFERROR(SUMIFS(INDEX('Soruce file '!$A:$Z, 0, MATCH("Night Driving", 'Soruce file '!$1:$1, 0)), INDEX('Soruce file '!$A:$Z, 0, MATCH("Date", 'Soruce file '!$1:$1, 0)), ">="&$B$1, INDEX('Soruce file '!$A:$Z, 0, MATCH("Date", 'Soruce file '!$1:$1, 0)), "<="&EOMONTH($B$1,0), INDEX('Soruce file '!$A:$Z, 0, MATCH("GA*", 'Soruce file '!$1:$1, 0)), $A4), 0) -> 0 | L4: =SUM(B4:K4) -> 5
A5: Baghpat | B5: =IFERROR(SUMIFS(INDEX('Soruce file '!$A:$Z, 0, MATCH("Mobile Usage", 'Soruce file '!$1:$1, 0)), INDEX('Soruce file '!$A:$Z, 0, MATCH("Date", 'Soruce file '!$1:$1, 0)), ">="&$B$1, INDEX('Soruce file '!$A:$Z, 0, MATCH("Date", 'Soruce file '!$1:$1, 0)), "<="&EOMONTH($B$1,0), INDEX('Soruce file '!$A:$Z, 0, MATCH("GA*", 'Soruce file '!$1:$1, 0)), $A5), 0) -> 3 | C5: =IFERROR(SUMIFS(INDEX('Soruce file '!$A:$Z, 0, MATCH("No Seatbelt", 'Soruce file '!$1:$1, 0)), INDEX('Soruce file '!$A:$Z, 0, MATCH("Date", 'Soruce file '!$1:$1, 0)), ">="&$B$1, INDEX('Soruce file '!$A:$Z, 0, MATCH("Date", 'Soruce file '!$1:$1, 0)), "<="&EOMONTH($B$1,0), INDEX('Soruce file '!$A:$Z, 0, MATCH("GA*", 'Soruce file '!$1:$1, 0)), $A5), 0) -> 1 | D5: =IFERROR(SUMIFS(INDEX('Soruce file '!$A:$Z, 0, MATCH("Yawning", 'Soruce file '!$1:$1, 0)), INDEX('Soruce file '!$A:$Z, 0, MATCH("Date", 'Soruce file '!$1:$1, 0)), ">="&$B$1, INDEX('Soruce file '!$A:$Z, 0, MATCH("Date", 'Soruce file '!$1:$1, 0)), "<="&EOMONTH($B$1,0), INDEX('Soruce file '!$A:$Z, 0, MATCH("GA*", 'Soruce file '!$1:$1, 0)), $A5), 0) -> 0 | E5: =IFERROR(SUMIFS(INDEX('Soruce file '!$A:$Z, 0, MATCH("Fatigue", 'Soruce file '!$1:$1, 0)), INDEX('Soruce file '!$A:$Z, 0, MATCH("Date", 'Soruce file '!$1:$1, 0)), ">="&$B$1, INDEX('Soruce file '!$A:$Z, 0, MATCH("Date", 'Soruce file '!$1:$1, 0)), "<="&EOMONTH($B$1,0), INDEX('Soruce file '!$A:$Z, 0, MATCH("GA*", 'Soruce file '!$1:$1, 0)), $A5), 0) -> 0 | F5: =IFERROR(SUMIFS(INDEX('Soruce file '!$A:$Z, 0, MATCH("Harsh Braking", 'Soruce file '!$1:$1, 0)), INDEX('Soruce file '!$A:$Z, 0, MATCH("Date", 'Soruce file '!$1:$1, 0)), ">="&$B$1, INDEX('Soruce file '!$A:$Z, 0, MATCH("Date", 'Soruce file '!$1:$1, 0)), "<="&EOMONTH($B$1,0), INDEX('Soruce file '!$A:$Z, 0, MATCH("GA*", 'Soruce file '!$1:$1, 0)), $A5), 0) -> 0 | G5: =IFERROR(SUMIFS(INDEX('Soruce file '!$A:$Z, 0, MATCH("Overspeed", 'Soruce file '!$1:$1, 0)), INDEX('Soruce file '!$A:$Z, 0, MATCH("Date", 'Soruce file '!$1:$1, 0)), ">="&$B$1, INDEX('Soruce file '!$A:$Z, 0, MATCH("Date", 'Soruce file '!$1:$1, 0)), "<="&EOMONTH($B$1,0), INDEX('Soruce file '!$A:$Z, 0, MATCH("GA*", 'Soruce file '!$1:$1, 0)), $A5), 0) -> 0 | H5: =IFERROR(SUMIFS(INDEX('Soruce file '!$A:$Z, 0, MATCH("Sudden Acceleration", 'Soruce file '!$1:$1, 0)), INDEX('Soruce file '!$A:$Z, 0, MATCH("Date", 'Soruce file '!$1:$1, 0)), ">="&$B$1, INDEX('Soruce file '!$A:$Z, 0, MATCH("Date", 'Soruce file '!$1:$1, 0)), "<="&EOMONTH($B$1,0), INDEX('Soruce file '!$A:$Z, 0, MATCH("GA*", 'Soruce file '!$1:$1, 0)), $A5), 0) -> 0 | I5: =IFERROR(SUMIFS(INDEX('Soruce file '!$A:$Z, 0, MATCH("Camera Anomaly", 'Soruce file '!$1:$1, 0)), INDEX('Soruce file '!$A:$Z, 0, MATCH("Date", 'Soruce file '!$1:$1, 0)), ">="&$B$1, INDEX('Soruce file '!$A:$Z, 0, MATCH("Date", 'Soruce file '!$1:$1, 0)), "<="&EOMONTH($B$1,0), INDEX('Soruce file '!$A:$Z, 0, MATCH("GA*", 'Soruce file '!$1:$1, 0)), $A5), 0) -> 0 | J5: =IFERROR(SUMIFS(INDEX('Soruce file '!$A:$Z, 0, MATCH("CD", 'Soruce file '!$1:$1, 0)), INDEX('Soruce file '!$A:$Z, 0, MATCH("Date", 'Soruce file '!$1:$1, 0)), ">="&$B$1, INDEX('Soruce file '!$A:$Z, 0, MATCH("Date", 'Soruce file '!$1:$1, 0)), "<="&EOMONTH($B$1,0), INDEX('Soruce file '!$A:$Z, 0, MATCH("GA*", 'Soruce file '!$1:$1, 0)), $A5), 0) -> 0 | K5: =IFERROR(SUMIFS(INDEX('Soruce file '!$A:$Z, 0, MATCH("Night Driving", 'Soruce file '!$1:$1, 0)), INDEX('Soruce file '!$A:$Z, 0, MATCH("Date", 'Soruce file '!$1:$1, 0)), ">="&$B$1, INDEX('Soruce file '!$A:$Z, 0, MATCH("Date", 'Soruce file '!$1:$1, 0)), "<="&EOMONTH($B$1,0), INDEX('Soruce file '!$A:$Z, 0, MATCH("GA*", 'Soruce file '!$1:$1, 0)), $A5), 0) -> 0 | L5: =SUM(B5:K5) -> 4
A6: Begusarai | B6: =IFERROR(SUMIFS(INDEX('Soruce file '!$A:$Z, 0, MATCH("Mobile Usage", 'Soruce file '!$1:$1, 0)), INDEX('Soruce file '!$A:$Z, 0, MATCH("Date", 'Soruce file '!$1:$1, 0)), ">="&$B$1, INDEX('Soruce file '!$A:$Z, 0, MATCH("Date", 'Soruce file '!$1:$1, 0)), "<="&EOMONTH($B$1,0), INDEX('Soruce file '!$A:$Z, 0, MATCH("GA*", 'Soruce file '!$1:$1, 0)), $A6), 0) -> 0 | C6: =IFERROR(SUMIFS(INDEX('Soruce file '!$A:$Z, 0, MATCH("No Seatbelt", 'Soruce file '!$1:$1, 0)), INDEX('Soruce file '!$A:$Z, 0, MATCH("Date", 'Soruce file '!$1:$1, 0)), ">="&$B$1, INDEX('Soruce file '!$A:$Z, 0, MATCH("Date", 'Soruce file '!$1:$1, 0)), "<="&EOMONTH($B$1,0), INDEX('Soruce file '!$A:$Z, 0, MATCH("GA*", 'Soruce file '!$1:$1, 0)), $A6), 0) -> 0 | D6: =IFERROR(SUMIFS(INDEX('Soruce file '!$A:$Z, 0, MATCH("Yawning", 'Soruce file '!$1:$1, 0)), INDEX('Soruce file '!$A:$Z, 0, MATCH("Date", 'Soruce file '!$1:$1, 0)), ">="&$B$1, INDEX('Soruce file '!$A:$Z, 0, MATCH("Date", 'Soruce file '!$1:$1, 0)), "<="&EOMONTH($B$1,0), INDEX('Soruce file '!$A:$Z, 0, MATCH("GA*", 'Soruce file '!$1:$1, 0)), $A6), 0) -> 0 | E6: =IFERROR(SUMIFS(INDEX('Soruce file '!$A:$Z, 0, MATCH("Fatigue", 'Soruce file '!$1:$1, 0)), INDEX('Soruce file '!$A:$Z, 0, MATCH("Date", 'Soruce file '!$1:$1, 0)), ">="&$B$1, INDEX('Soruce file '!$A:$Z, 0, MATCH("Date", 'Soruce file '!$1:$1, 0)), "<="&EOMONTH($B$1,0), INDEX('Soruce file '!$A:$Z, 0, MATCH("GA*", 'Soruce file '!$1:$1, 0)), $A6), 0) -> 0 | F6: =IFERROR(SUMIFS(INDEX('Soruce file '!$A:$Z, 0, MATCH("Harsh Braking", 'Soruce file '!$1:$1, 0)), INDEX('Soruce file '!$A:$Z, 0, MATCH("Date", 'Soruce file '!$1:$1, 0)), ">="&$B$1, INDEX('Soruce file '!$A:$Z, 0, MATCH("Date", 'Soruce file '!$1:$1, 0)), "<="&EOMONTH($B$1,0), INDEX('Soruce file '!$A:$Z, 0, MATCH("GA*", 'Soruce file '!$1:$1, 0)), $A6), 0) -> 0 | G6: =IFERROR(SUMIFS(INDEX('Soruce file '!$A:$Z, 0, MATCH("Overspeed", 'Soruce file '!$1:$1, 0)), INDEX('Soruce file '!$A:$Z, 0, MATCH("Date", 'Soruce file '!$1:$1, 0)), ">="&$B$1, INDEX('Soruce file '!$A:$Z, 0, MATCH("Date", 'Soruce file '!$1:$1, 0)), "<="&EOMONTH($B$1,0), INDEX('Soruce file '!$A:$Z, 0, MATCH("GA*", 'Soruce file '!$1:$1, 0)), $A6), 0) -> 0 | H6: =IFERROR(SUMIFS(INDEX('Soruce file '!$A:$Z, 0, MATCH("Sudden Acceleration", 'Soruce file '!$1:$1, 0)), INDEX('Soruce file '!$A:$Z, 0, MATCH("Date", 'Soruce file '!$1:$1, 0)), ">="&$B$1, INDEX('Soruce file '!$A:$Z, 0, MATCH("Date", 'Soruce file '!$1:$1, 0)), "<="&EOMONTH($B$1,0), INDEX('Soruce file '!$A:$Z, 0, MATCH("GA*", 'Soruce file '!$1:$1, 0)), $A6), 0) -> 0 | I6: =IFERROR(SUMIFS(INDEX('Soruce file '!$A:$Z, 0, MATCH("Camera Anomaly", 'Soruce file '!$1:$1, 0)), INDEX('Soruce file '!$A:$Z, 0, MATCH("Date", 'Soruce file '!$1:$1, 0)), ">="&$B$1, INDEX('Soruce file '!$A:$Z, 0, MATCH("Date", 'Soruce file '!$1:$1, 0)), "<="&EOMONTH($B$1,0), INDEX('Soruce file '!$A:$Z, 0, MATCH("GA*", 'Soruce file '!$1:$1, 0)), $A6), 0) -> 0 | J6: =IFERROR(SUMIFS(INDEX('Soruce file '!$A:$Z, 0, MATCH("CD", 'Soruce file '!$1:$1, 0)), INDEX('Soruce file '!$A:$Z, 0, MATCH("Date", 'Soruce file '!$1:$1, 0)), ">="&$B$1, INDEX('Soruce file '!$A:$Z, 0, MATCH("Date", 'Soruce file '!$1:$1, 0)), "<="&EOMONTH($B$1,0), INDEX('Soruce file '!$A:$Z, 0, MATCH("GA*", 'Soruce file '!$1:$1, 0)), $A6), 0) -> 0 | K6: =IFERROR(SUMIFS(INDEX('Soruce file '!$A:$Z, 0, MATCH("Night Driving", 'Soruce file '!$1:$1, 0)), INDEX('Soruce file '!$A:$Z, 0, MATCH("Date", 'Soruce file '!$1:$1, 0)), ">="&$B$1, INDEX('Soruce file '!$A:$Z, 0, MATCH("Date", 'Soruce file '!$1:$1, 0)), "<="&EOMONTH($B$1,0), INDEX('Soruce file '!$A:$Z, 0, MATCH("GA*", 'Soruce file '!$1:$1, 0)), $A6), 0) -> 0 | L6: =SUM(B6:K6) -> 0
A7: Bhopal | B7: =IFERROR(SUMIFS(INDEX('Soruce file '!$A:$Z, 0, MATCH("Mobile Usage", 'Soruce file '!$1:$1, 0)), INDEX('Soruce file '!$A:$Z, 0, MATCH("Date", 'Soruce file '!$1:$1, 0)), ">="&$B$1, INDEX('Soruce file '!$A:$Z, 0, MATCH("Date", 'Soruce file '!$1:$1, 0)), "<="&EOMONTH($B$1,0), INDEX('Soruce file '!$A:$Z, 0, MATCH("GA*", 'Soruce file '!$1:$1, 0)), $A7), 0) -> 9 | C7: =IFERROR(SUMIFS(INDEX('Soruce file '!$A:$Z, 0, MATCH("No Seatbelt", 'Soruce file '!$1:$1, 0)), INDEX('Soruce file '!$A:$Z, 0, MATCH("Date", 'Soruce file '!$1:$1, 0)), ">="&$B$1, INDEX('Soruce file '!$A:$Z, 0, MATCH("Date", 'Soruce file '!$1:$1, 0)), "<="&EOMONTH($B$1,0), INDEX('Soruce file '!$A:$Z, 0, MATCH("GA*", 'Soruce file '!$1:$1, 0)), $A7), 0) -> 3 | D7: =IFERROR(SUMIFS(INDEX('Soruce file '!$A:$Z, 0, MATCH("Yawning", 'Soruce file '!$1:$1, 0)), INDEX('Soruce file '!$A:$Z, 0, MATCH("Date", 'Soruce file '!$1:$1, 0)), ">="&$B$1, INDEX('Soruce file '!$A:$Z, 0, MATCH("Date", 'Soruce file '!$1:$1, 0)), "<="&EOMONTH($B$1,0), INDEX('Soruce file '!$A:$Z, 0, MATCH("GA*", 'Soruce file '!$1:$1, 0)), $A7), 0) -> 0 | E7: =IFERROR(SUMIFS(INDEX('Soruce file '!$A:$Z, 0, MATCH("Fatigue", 'Soruce file '!$1:$1, 0)), INDEX('Soruce file '!$A:$Z, 0, MATCH("Date", 'Soruce file '!$1:$1, 0)), ">="&$B$1, INDEX('Soruce file '!$A:$Z, 0, MATCH("Date", 'Soruce file '!$1:$1, 0)), "<="&EOMONTH($B$1,0), INDEX('Soruce file '!$A:$Z, 0, MATCH("GA*", 'Soruce file '!$1:$1, 0)), $A7), 0) -> 1 | F7: =IFERROR(SUMIFS(INDEX('Soruce file '!$A:$Z, 0, MATCH("Harsh Braking", 'Soruce file '!$1:$1, 0)), INDEX('Soruce file '!$A:$Z, 0, MATCH("Date", 'Soruce file '!$1:$1, 0)), ">="&$B$1, INDEX('Soruce file '!$A:$Z, 0, MATCH("Date", 'Soruce file '!$1:$1, 0)), "<="&EOMONTH($B$1,0), INDEX('Soruce file '!$A:$Z, 0, MATCH("GA*", 'Soruce file '!$1:$1, 0)), $A7), 0) -> 0 | G7: =IFERROR(SUMIFS(INDEX('Soruce file '!$A:$Z, 0, MATCH("Overspeed", 'Soruce file '!$1:$1, 0)), INDEX('Soruce file '!$A:$Z, 0, MATCH("Date", 'Soruce file '!$1:$1, 0)), ">="&$B$1, INDEX('Soruce file '!$A:$Z, 0, MATCH("Date", 'Soruce file '!$1:$1, 0)), "<="&EOMONTH($B$1,0), INDEX('Soruce file '!$A:$Z, 0, MATCH("GA*", 'Soruce file '!$1:$1, 0)), $A7), 0) -> 1 | H7: =IFERROR(SUMIFS(INDEX('Soruce file '!$A:$Z, 0, MATCH("Sudden Acceleration", 'Soruce file '!$1:$1, 0)), INDEX('Soruce file '!$A:$Z, 0, MATCH("Date", 'Soruce file '!$1:$1, 0)), ">="&$B$1, INDEX('Soruce file '!$A:$Z, 0, MATCH("Date", 'Soruce file '!$1:$1, 0)), "<="&EOMONTH($B$1,0), INDEX('Soruce file '!$A:$Z, 0, MATCH("GA*", 'Soruce file '!$1:$1, 0)), $A7), 0) -> 0 | I7: =IFERROR(SUMIFS(INDEX('Soruce file '!$A:$Z, 0, MATCH("Camera Anomaly", 'Soruce file '!$1:$1, 0)), INDEX('Soruce file '!$A:$Z, 0, MATCH("Date", 'Soruce file '!$1:$1, 0)), ">="&$B$1, INDEX('Soruce file '!$A:$Z, 0, MATCH("Date", 'Soruce file '!$1:$1, 0)), "<="&EOMONTH($B$1,0), INDEX('Soruce file '!$A:$Z, 0, MATCH("GA*", 'Soruce file '!$1:$1, 0)), $A7), 0) -> 0 | J7: =IFERROR(SUMIFS(INDEX('Soruce file '!$A:$Z, 0, MATCH("CD", 'Soruce file '!$1:$1, 0)), INDEX('Soruce file '!$A:$Z, 0, MATCH("Date", 'Soruce file '!$1:$1, 0)), ">="&$B$1, INDEX('Soruce file '!$A:$Z, 0, MATCH("Date", 'Soruce file '!$1:$1, 0)), "<="&EOMONTH($B$1,0), INDEX('Soruce file '!$A:$Z, 0, MATCH("GA*", 'Soruce file '!$1:$1, 0)), $A7), 0) -> 0 | K7: =IFERROR(SUMIFS(INDEX('Soruce file '!$A:$Z, 0, MATCH("Night Driving", 'Soruce file '!$1:$1, 0)), INDEX('Soruce file '!$A:$Z, 0, MATCH("Date", 'Soruce file '!$1:$1, 0)), ">="&$B$1, INDEX('Soruce file '!$A:$Z, 0, MATCH("Date", 'Soruce file '!$1:$1, 0)), "<="&EOMONTH($B$1,0), INDEX('Soruce file '!$A:$Z, 0, MATCH("GA*", 'Soruce file '!$1:$1, 0)), $A7), 0) -> 0 | L7: =SUM(B7:K7) -> 14
